Workbook

Sheet DATOS GENERALES 
A1: ORDENES DE PRODUCCION AGOSTO | B1: DETALLE | C1: MAQUINA | D1: PRODUCTO | E1: CALIBRACION | F1: MTS PEDIDO | G1: MTS PRODUCCION | H1: MTS FACRURADOS | I1: STOCK | J1: MTS FALLA | K1: KG DE FALLA | L1: % FALLA | M1: EFICIENCIA MAQUINA | N1: INGRESO | O1: APROBACION | P1: INICIO PRODUCCION EN MAQUINA | Q1: FECHA URDIDO | R1: DIAS | S1: FIN PRODUCCION | T1: DIAS | U1: FECHA FIN ENVOLTURA | V1: DIAS | W1: FECHA DE FACTURACION | X1: DIAS | Y1: DIAS TOTAL DE ENTREGA | Z1: EFICIENCIA DE ENTREGA | AA1: ESTADO | AB1: CLIENTE | AC1: MTS X HORA | AD1: TIRAS | AE1: HORARIO 10/24H | AF1: DIAS ESTANDAR DE PRODUCCION | AG1: DIAS REALES DE PRODUCCION | AH1: FECHA REAL FINAL PRODUCCION | AI1: OBSERVACIONES
A2: OP40 JUL | B2: REATA CONFECCION ZARGA COLCHON | C2: KY#7 | D2: REATA | E2: JAVIER | F2: 7800 | G2: 8925 | H2: 8500 | I2: 1080 | J2: 233 | K2: 2.1 | L2: =+J2/G2 -> 0.026106443 | M2: 0.96 | N2: 46231 | O2: 46232 | P2: 46239 | Q2: 46237 | R2: =IF(Q2="","",NETWORKDAYS(N2,Q2)) -> 5 | S2: 46240 | T2: =IF(S2="","",NETWORKDAYS(Q2,S2)) -> 4 | U2: 46245 | V2: =IF(U2="","",NETWORKDAYS(S2,U2)) -> 4 | W2: 46247 | X2: =IF(W2="","",NETWORKDAYS(U2,W2)) -> 3 | Y2: =IF(W2="","",NETWORKDAYS(N2,W2)) -> 13 | Z2: =IF(Y2="","",IF(Y2<=20,"EFICIENTE","NO EFICIENTE")) -> EFICIENTE | AA2: TERMINADO | AB2: SICORMATRESS | AC2: 56.04 | AD2: 6 | AE2: 24 | AF2: =ROUNDUP((F2*1/(AC2*AD2*M2*AE2)),0) -> 2 | AG2: =32/24 -> 1.3333333 | AH2: =WORKDAY.INTL(P2,AF2,1,0) -> 46241
A3: OP09 JUL | B3: REATA SANDAIA TUBULAR LUREX 25MM | C3: KY#5 | D3: REATA | E3: OSCAR | F3: 4000 | G3: 4848 | H3: 4250 | I3: - | J3: 578 | K3: 13.4 | L3: =+J3/G3 -> 0.11922442 | M3: 0.8 | N3: 46205 | O3: 46205 | P3: 46238 | Q3: 46234 | R3: =IF(Q3="","",NETWORKDAYS(N3,Q3)) -> 22 | S3: 46240 | T3: =IF(S3="","",NETWORKDAYS(Q3,S3)) -> 5 | U3: 46241 | V3: =IF(U3="","",NETWORKDAYS(S3,U3)) -> 2 | W3: 46246 | X3: =IF(W3="","",NETWORKDAYS(U3,W3)) -> 4 | Y3: =IF(W3="","",NETWORKDAYS(N3,W3)) -> 30 | Z3: =IF(Y3="","",IF(Y3<=32,"EFICIENTE","NO EFICIENTE")) -> EFICIENTE | AA3: TERMINADO | AB3: IMPORTIZ | AC3: 45.72 | AD3: 6 | AE3: 24 | AF3: =ROUNDUP((F3*1/(AC3*AD3*M3*AE3)),0) -> 1 | AG3: =30/24 -> 1.25 | AH3: =WORKDAY.INTL(P3,AF3,1,0) -> 46239 | AK3: EFICIENCIA ENTREGA
A4: OP36 JUL | B4: ELASTICO ZAPATO REFORZADO 100 MM | C4: KY#18 | D4: ELASTICO | E4: JAVIER | F4: 460 | G4: 547 | L4: =+J4/G4 -> 0 | M4: 1 | N4: 46224 | O4: 46224 | P4: 46238 | Q4: 46232 | R4: =IF(Q4="","",NETWORKDAYS(N4,Q4)) -> 7 | S4: 46238 | T4: =IF(S4="","",NETWORKDAYS(Q4,S4)) -> 5 | U4: 46252 | V4: =IF(U4="","",NETWORKDAYS(S4,U4)) -> 11 | W4: 46224 | X4: =IF(W4="","",NETWORKDAYS(U4,W4)) -> -21 | Y4: =IF(W4="","",NETWORKDAYS(N4,W4)) -> 1 | Z4: =IF(Y4="","",IF(Y4<=20,"EFICIENTE","NO EFICIENTE")) -> EFICIENTE | AA4: TERMINADO | AB4: ACHUPATIN | AC4: 19.32 | AD4: 2 | AE4: 13 | AF4: =ROUNDUP((F4*1/(AC4*AD4*M4*AE4)),0) -> 1 | AG4: =13/13 -> 1 | AH4: =WORKDAY.INTL(P4,AF4,1,0) -> 46239 | AK4: EFICIENTE | AL4: 26 | AT4: VERDE | AU4: 2
A5: OP41 JUL | B5: ELASTICO ZAPATO REFORZADO 50MM | C5: KY#13 | D5: ELASTICO | E5: JESSICA | F5: 1380 | G5: 1917 | H5: 1236 | I5: 1185 | J5: 64 | K5: 304 | L5: =+J5/G5 -> 0.033385498 | M5: 0.84 | N5: 46233 | O5: 46234 | P5: 46245 | Q5: 46239 | R5: =IF(Q5="","",NETWORKDAYS(N5,Q5)) -> 5 | S5: 46247 | T5: =IF(S5="","",NETWORKDAYS(Q5,S5)) -> 7 | U5: 46248 | V5: =IF(U5="","",NETWORKDAYS(S5,U5)) -> 2 | W5: 46241 | X5: =IF(W5="","",NETWORKDAYS(U5,W5)) -> -6 | Y5: =IF(W5="","",NETWORKDAYS(N5,W5)) -> 7 | Z5: =IF(Y5="","",IF(Y5<=20,"EFICIENTE","NO EFICIENTE")) -> EFICIENTE | AA5: TERMINADO | AB5: PAISA | AC5: 16.92 | AD5: 2 | AE5: 24 | AF5: =ROUNDUP((F5*1/(AC5*AD5*M5*AE5)),0) -> 3 | AG5: =53/24 -> 2.2083333 | AH5: =WORKDAY.INTL(P5,AF5,1,0) -> 46248 | AK5: NO EFICIENTE | AL5: 10 | AT5: ROJO | AU5: 3
A6: OP39 JUL | B6: REATA CONFECCION EMPALMADA 20MM | C6: KY#2 | D6: REATA | E6: CARLOS | F6: 4000 | G6: 3649 | H6: 3150 | I6: - | J6: 318 | K6: 2.35 | L6: =+J6/G6 -> 0.087147164 | M6: 0.75 | N6: 46231 | O6: 46232 | P6: 46240 | Q6: 46238 | R6: =IF(Q6="","",NETWORKDAYS(N6,Q6)) -> 6 | S6: 46247 | T6: =IF(S6="","",NETWORKDAYS(Q6,S6)) -> 8 | U6: 46251 | V6: =IF(U6="","",NETWORKDAYS(S6,U6)) -> 3 | W6: 46252 | X6: =IF(W6="","",NETWORKDAYS(U6,W6)) -> 2 | Y6: =IF(W6="","",NETWORKDAYS(N6,W6)) -> 16 | Z6: =IF(Y6="","",IF(Y6<=20,"EFICIENTE","NO EFICIENTE")) -> EFICIENTE | AA6: TERMINADO | AB6: NUNEZ SANTIAGO | AC6: 48.96 | AD6: 4 | AE6: 24 | AF6: =ROUNDUP((F6*1/(AC6*AD6*M6*AE6)),0) -> 2 | AG6: =18/24 -> 0.75 | AH6: =WORKDAY.INTL(P6,AF6,1,0) -> 46244 | AK6: TOTAL | AL6: =SUM(AL4:AL5) -> 36 | AT6: TOTAL
A7: OP20 AGOS | B7: REATA CONFECCION ZARGA COLCHON | C7: KY#7 | D7: REATA | E7: CLAUDIO | F7: 6000 | G7: 6434 | H7: 6000 | I7: 400 | J7: 80 | K7: 0.72 | L7: =+J7/G7 -> 0.012433945 | M7: 0.8 | N7: 46239 | O7: 46240 | P7: 46249 | Q7: 46247 | R7: =IF(Q7="","",NETWORKDAYS(N7,Q7)) -> 7 | S7: 46251 | T7: =IF(S7="","",NETWORKDAYS(Q7,S7)) -> 3 | U7: 46253 | V7: =IF(U7="","",NETWORKDAYS(S7,U7)) -> 3 | W7: 46254 | X7: =IF(W7="","",NETWORKDAYS(U7,W7)) -> 2 | Y7: =IF(W7="","",NETWORKDAYS(N7,W7)) -> 12 | Z7: =IF(Y7="","",IF(Y7<=20,"EFICIENTE","NO EFICIENTE")) -> EFICIENTE | AA7: TERMINADO | AB7: SICORMATRESS | AC7: 56.04 | AD7: 6 | AE7: 24 | AF7: =ROUNDUP((F7*1/(AC7*AD7*M7*AE7)),0) -> 1 | AG7: =32/24 -> 1.3333333 | AH7: =WORKDAY.INTL(P7,AF7,1,0) -> 46251
A8: OP42 JUL | B8: ELASTICO ZAPATO PES 8MM | C8: JAQ#4 | D8: ELASTICO | E8: CLAUDIO | F8: 3680 | G8: 4387 | H8: 4048 | I8: - | J8: 316 | K8: 1.71 | L8: =+J8/G8 -> 0.072031001 | M8: 0.75 | N8: 46233 | O8: 46234 | P8: 46246 | Q8: 46239 | R8: =IF(Q8="","",NETWORKDAYS(N8,Q8)) -> 5 | S8: 46251 | T8: =IF(S8="","",NETWORKDAYS(Q8,S8)) -> 9 | U8: 46254 | V8: =IF(U8="","",NETWORKDAYS(S8,U8)) -> 4 | W8: 46254 | X8: =IF(W8="","",NETWORKDAYS(U8,W8)) -> 1 | Y8: =IF(W8="","",NETWORKDAYS(N8,W8)) -> 16 | Z8: =IF(Y8="","",IF(Y8<=20,"EFICIENTE","NO EFICIENTE")) -> EFICIENTE | AA8: TERMINADO | AB8: NUNEZ SANTIAGO | AC8: 23.76 | AD8: 4 | AE8: 24 | AF8: =ROUNDUP((F8*1/(AC8*AD8*M8*AE8)),0) -> 3 | AG8: =75/24 -> 3.125 | AH8: =WORKDAY.INTL(P8,AF8,1,0) -> 46251
A9: OP03 04 AGOS | B9: REATA MOCHILA DELGADA 10 15 MM | C9: JAQ#10 | D9: REATA | E9: CARLOS | F9: =13600+13600 -> 27200 | G9: 19497 | H9: 19400 | L9: =+J9/G9 -> 0 | M9: 0.62 | N9: 46234 | O9: 46237 | P9: 46252 | Q9: 46247 | R9: =IF(Q9="","",NETWORKDAYS(N9,Q9)) -> 10 | T9: =IF(S9="","",NETWORKDAYS(Q9,S9)) | V9: =IF(U9="","",NETWORKDAYS(S9,U9)) | W9: 46254 | X9: =IF(W9="","",NETWORKDAYS(U9,W9)) -> 33039 | Y9: =IF(W9="","",NETWORKDAYS(N9,W9)) -> 15 | Z9: =IF(Y9="","",IF(Y9<=20,"EFICIENTE","NO EFICIENTE")) -> EFICIENTE | AA9: PARADA HACIENDO MANTENIMIENTO SIGUE STOCK | AB9: FANDINGO JENNIFER +STOCK | AC9: 84 | AD9: 6 | AE9: 24 | AF9: =ROUNDUP((F9*1/(AC9*AD9*M9*AE9)),0) -> 4 | AH9: =WORKDAY.INTL(P9,AF9,1,0) -> 46258
A10: OP02 AGOS | B10: REATA MOCHILA GRUES TUBULAR OJAL 10MM | C10: JAQ#5 | D10: REATA | E10: CARLOS | F10: 6000 | G10: 5873 | H10: 5800 | I10: - | J10: 48 | K10: 0.3 | L10: =+J10/G10 -> 0.0081729951 | M10: 0.87 | N10: 46234 | O10: 46234 | P10: 46254 | Q10: 46251 | R10: =IF(Q10="","",NETWORKDAYS(N10,Q10)) -> 12 | S10: 46258 | T10: =IF(S10="","",NETWORKDAYS(Q10,S10)) -> 6 | U10: 46259 | V10: =IF(U10="","",NETWORKDAYS(S10,U10)) -> 2 | W10: 46259 | X10: =IF(W10="","",NETWORKDAYS(U10,W10)) -> 1 | Y10: =IF(W10="","",NETWORKDAYS(N10,W10)) -> 18 | Z10: =IF(Y10="","",IF(Y10<=20,"EFICIENTE","NO EFICIENTE")) -> EFICIENTE | AA10: TERMINADO | AB10: GUTIERREZ+STOCK | AC10: 41.88 | AD10: 4 | AE10: 24 | AF10: =ROUNDUP((F10*1/(AC10*AD10*M10*AE10)),0) -> 2 | AG10: =40/24 -> 1.6666667 | AH10: =WORKDAY.INTL(P10,AF10,1,0) -> 46258
A11: OP41 AGOS | B11: REATA CONFECCION EMPALMADA 10MM | C11: KY#2 | D11: REATA | E11: OSCAR | F11: 4000 | G11: 3757 | H11: 3500 | I11: 57 | J11: 143 | K11: 0.53 | L11: =+J11/G11 -> 0.038062284 | M11: 0.82 | N11: 46248 | O11: 46251 | P11: 46258 | Q11: 46255 | R11: =IF(Q11="","",NETWORKDAYS(N11,Q11)) -> 6 | S11: 46258 | T11: =IF(S11="","",NETWORKDAYS(Q11,S11)) -> 2 | U11: 46259 | V11: =IF(U11="","",NETWORKDAYS(S11,U11)) -> 2 | W11: 46259 | X11: =IF(W11="","",NETWORKDAYS(U11,W11)) -> 1 | Y11: =IF(W11="","",NETWORKDAYS(N11,W11)) -> 8 | Z11: =IF(Y11="","",IF(Y11<=20,"EFICIENTE","NO EFICIENTE")) -> EFICIENTE | AA11: TERMINADO | AB11: ROSA ELVIA | AC11: 49.32 | AD11: 6 | AE11: 24 | AF11: =ROUNDUP((F11*1/(AC11*AD11*M11*AE11)),0) -> 1 | AH11: =WORKDAY.INTL(P11,AF11,1,0) -> 46259
A12: OP07 AGOS | B12: REATA CONFECCION EMPLAMDA GRUESA 15MM PATUCA | C12: KY#9 | D12: REATA | E12: CLAUDIO | F12: 15000 | G12: 14195 | H12: 13650 | I12: 10076 | J12: 276 | K12: 0.8 | L12: =+J12/G12 -> 0.019443466 | M12: 0.8 | N12: 46234 | O12: 46234 | P12: 46240 | Q12: 46241 | R12: =IF(Q12="","",NETWORKDAYS(N12,Q12)) -> 6 | S12: 46253 | T12: =IF(S12="","",NETWORKDAYS(Q12,S12)) -> 9 | U12: 46255 | V12: =IF(U12="","",NETWORKDAYS(S12,U12)) -> 3 | W12: 46255 | X12: =IF(W12="","",NETWORKDAYS(U12,W12)) -> 1 | Y12: =IF(W12="","",NETWORKDAYS(N12,W12)) -> 16 | Z12: =IF(Y12="","",IF(Y12<=20,"EFICIENTE","NO EFICIENTE")) -> EFICIENTE | AA12: TERMINADO | AB12: NUNEZ SANTIAGO | AC12: 47.52 | AD12: 6 | AE12: 24 | AF12: =ROUNDUP((F12*1/(AC12*AD12*M12*AE12)),0) -> 3 | AG12: =151/24 -> 6.2916667 | AH12: =WORKDAY.INTL(P12,AF12,1,0) -> 46245
A13: OP01 AGOS | B13: ELASTICO ZAPATO REFORZADO 60MM | C13: KY#13 | D13: ELASTICO | E13: JOSE | F13: 2944 | G13: 1612 | H13: 2760 | I13: - | J13: 62 | K13: 3.71 | L13: =+J13/G13 -> 0.038461538 | M13: 0.85 | N13: 46234 | O13: 46234 | P13: 46252 | Q13: 46247 | R13: =IF(Q13="","",NETWORKDAYS(N13,Q13)) -> 10 | S13: 46260 | T13: =IF(S13="","",NETWORKDAYS(Q13,S13)) -> 10 | U13: 46273 | V13: =IF(U13="","",NETWORKDAYS(S13,U13)) -> 10 | W13: 46238 | X13: =IF(W13="","",NETWORKDAYS(U13,W13)) -> -26 | Y13: =IF(W13="","",NETWORKDAYS(N13,W13)) -> 3 | Z13: =IF(Y13="","",IF(Y13<=20,"EFICIENTE","NO EFICIENTE")) -> EFICIENTE | AA13: TERMINADO | AB13: SANCHEZ MARIBEL +STOCK | AC13: 16.92 | AD13: 2 | AE13: 24 | AF13: =ROUNDUP((F13*1/(AC13*AD13*M13*AE13)),0) -> 5 | AH13: =WORKDAY.INTL(P13,AF13,1,0) -> 46259
A14: OP37 AGOS | B14: REATA CONFECCION ZARGA COLCHON | C14: KY#7 | D14: REATA | E14: JAVIER | F14: 36000 | G14: 29811 | H14: 22000 | I14: - | J14: 696 | K14: 6.27 | L14: =+J14/G14 -> 0.023347087 | M14: 0.66 | N14: 46248 | O14: 46248 | P14: 46253 | Q14: 46251 | R14: =IF(Q14="","",NETWORKDAYS(N14,Q14)) -> 2 | S14: 46262 | T14: =IF(S14="","",NETWORKDAYS(Q14,S14)) -> 10 | U14: 46262 | V14: =IF(U14="","",NETWORKDAYS(S14,U14)) -> 1 | W14: 46262 | X14: =IF(W14="","",NETWORKDAYS(U14,W14)) -> 1 | Y14: =IF(W14="","",NETWORKDAYS(N14,W14)) -> 11 | Z14: =IF(Y14="","",IF(Y14<=20,"EFICIENTE","NO EFICIENTE")) -> EFICIENTE | AA14: TERMINADO | AB14: SICORMATRESS | AC14: 56.04 | AD14: 6 | AE14: 24 | AF14: =ROUNDUP((F14*1/(AC14*AD14*M14*AE14)),0) -> 7 | AH14: =WORKDAY.INTL(P14,AF14,1,0) -> 46262
A15: OP30 AGOS | B15: REATA SANDALIA TUBULAR 35MM | C15: JAQ#6 | D15: REATA | E15: JOSE | F15: 4000 | G15: 3767 | H15: 3350 | I15: 45 | J15: 481 | K15: 6.36 | L15: =+J15/G15 -> 0.12768782 | M15: 0.59 | N15: 46245 | O15: 46247 | P15: 46262 | Q15: 46253 | R15: =IF(Q15="","",NETWORKDAYS(N15,Q15)) -> 7 | S15: 46265 | T15: =IF(S15="","",NETWORKDAYS(Q15,S15)) -> 9 | U15: 46272 | V15: =IF(U15="","",NETWORKDAYS(S15,U15)) -> 6 | W15: 46272 | X15: =IF(W15="","",NETWORKDAYS(U15,W15)) -> 1 | Y15: =IF(W15="","",NETWORKDAYS(N15,W15)) -> 20 | Z15: =IF(Y15="","",IF(Y15<=20,"EFICIENTE","NO EFICIENTE")) -> EFICIENTE | AA15: TERMINADO | AB15: ALFONZO ZAMBRANO | AC15: 31.56 | AD15: 4 | AE15: 24 | AF15: =ROUNDUP((F15*1/(AC15*AD15*M15*AE15)),0) -> 3 | AH15: =WORKDAY.INTL(P15,AF15,1,0) -> 46267 | AI15: EN ESPERA SE TIENE QUE CAMBIAR LAS MEDIDAS
A16: OP33 AGOS | B16: ELASTICO BOSTON AZUL ACERO /TURQUEZA | C16: JAQ#2 | D16: ELASTICO | E16: JAVIER | F16: 5300 | G16: 3108 | H16: 4483 | I16: - | J16: 923.47 | K16: 4.53 | L16: =+J16/G16 -> 0.29712677 | M16: 0.74 | N16: 46246 | O16: 46246 | P16: 46258 | Q16: 46253 | R16: =IF(Q16="","",NETWORKDAYS(N16,Q16)) -> 6 | S16: 46262 | T16: =IF(S16="","",NETWORKDAYS(Q16,S16)) -> 8 | U16: 46266 | V16: =IF(U16="","",NETWORKDAYS(S16,U16)) -> 3 | W16: 46266 | X16: =IF(W16="","",NETWORKDAYS(U16,W16)) -> 1 | Y16: =IF(W16="","",NETWORKDAYS(N16,W16)) -> 15 | Z16: =IF(Y16="","",IF(Y16<=20,"EFICIENTE","NO EFICIENTE")) -> EFICIENTE | AA16: TERMINADO | AB16: BOSTON | AC16: 14.04 | AD16: 6 | AE16: 24 | AF16: =ROUNDUP((F16*1/(AC16*AD16*M16*AE16)),0) -> 4 | AG16: =93/24 -> 3.875 | AH16: =WORKDAY.INTL(P16,AF16,1,0) -> 46262
A17: OP34 AGOS | B17: REATA SANDALIA GRUESA 15MM | C17: JAQ#11 | D17: REATA | E17: JOSE | F17: 8000 | G17: 7896 | H17: 7900 | I17: 97 | J17: 351 | K17: 1.23 | L17: =+J17/G17 -> 0.044452888 | M17: 0.89 | N17: 46248 | O17: 46249 | P17: 46265 | Q17: 46261 | R17: =IF(Q17="","",NETWORKDAYS(N17,Q17)) -> 10 | S17: 46266 | T17: =IF(S17="","",NETWORKDAYS(Q17,S17)) -> 4 | U17: 46268 | V17: =IF(U17="","",NETWORKDAYS(S17,U17)) -> 3 | W17: 46269 | X17: =IF(W17="","",NETWORKDAYS(U17,W17)) -> 2 | Y17: =IF(W17="","",NETWORKDAYS(N17,W17)) -> 16 | Z17: =IF(Y17="","",IF(Y17<=20,"EFICIENTE","NO EFICIENTE")) -> EFICIENTE | AA17: TERMINADO | AB17: BURI VICTOR | AC17: 42.96 | AD17: 6 | AE17: 24 | AF17: =ROUNDUP((F17*1/(AC17*AD17*M17*AE17)),0) -> 2 | AH17: =WORKDAY.INTL(P17,AF17,1,0) -> 46267
A18: OP46 AGOS | B18: REATA SANDALIA TUBULAR 25MM | C18: KY#5 | D18: REATA | E18: CLAUDIO | F18: 5000 | G18: 4834 | H18: 4725 | I18: - | J18: 75 | K18: 1.84 | L18: =+J18/G18 -> 0.015515101 | M18: 1 | N18: 46252 | O18: 46254 | P18: 46267 | Q18: 46266 | R18: =IF(Q18="","",NETWORKDAYS(N18,Q18)) -> 11 | S18: 46269 | T18: =IF(S18="","",NETWORKDAYS(Q18,S18)) -> 4 | U18: 46272 | V18: =IF(U18="","",NETWORKDAYS(S18,U18)) -> 2 | W18: 46273 | X18: =IF(W18="","",NETWORKDAYS(U18,W18)) -> 2 | Y18: =IF(W18="","",NETWORKDAYS(N18,W18)) -> 16 | Z18: =IF(Y18="","",IF(Y18<=20,"EFICIENTE","NO EFICIENTE")) -> EFICIENTE | AA18: TERMINADO | AB18: IMPORTIZ | AC18: 47.64 | AD18: 4 | AE18: 24 | AF18: =ROUNDUP((F18*1/(AC18*AD18*M18*AE18)),0) -> 2 | AH18: =WORKDAY.INTL(P18,AF18,1,0) -> 46269
A19: OP24 AGOS | B19: ELASTICO CONFECCION FAJAS MEDICAS 25MM | C19: JAQ13 | D19: ELASTICO | E19: JOSE | F19: 10476 | G19: 7762 | I19: - | L19: =+J19/G19 -> 0 | M19: 0.77 | N19: 46246 | O19: 46247 | P19: 46258 | Q19: 46255 | R19: =IF(Q19="","",NETWORKDAYS(N19,Q19)) -> 8 | S19: 46272 | T19: =IF(S19="","",NETWORKDAYS(Q19,S19)) -> 12 | U19: 46269 | V19: =IF(U19="","",NETWORKDAYS(S19,U19)) -> -2 | W19: 46266 | X19: =IF(W19="","",NETWORKDAYS(U19,W19)) -> -4 | Y19: =IF(W19="","",NETWORKDAYS(N19,W19)) -> 15 | Z19: =IF(Y19="","",IF(Y19<=20,"EFICIENTE","NO EFICIENTE")) -> EFICIENTE | AA19: TERMINADO | AB19: BUENANO + STOCK | AC19: 19.44 | AD19: 6 | AE19: 24 | AF19: =ROUNDUP((F19*1/(AC19*AD19*M19*AE19)),0) -> 5 | AH19: =WORKDAY.INTL(P19,AF19,1,0) -> 46265
A20: OP45 AGO | B20: REATA SANDALIA TUBULAR GRUESA 2 CANALES 30MM | C20: KY#15 | D20: REATA | E20: CLAUDIO | F20: 6000 | G20: 6435 | H20: 6825 | I20: - | J20: 278 | K20: 12.01 | L20: =+J20/G20 -> 0.043201243 | M20: 0.62 | N20: 46252 | O20: 46254 | P20: 46265 | Q20: 46265 | R20: =IF(Q20="","",NETWORKDAYS(N20,Q20)) -> 10 | S20: 46268 | T20: =IF(S20="","",NETWORKDAYS(Q20,S20)) -> 4 | U20: 46273 | V20: =IF(U20="","",NETWORKDAYS(S20,U20)) -> 4 | W20: 46275 | X20: =IF(W20="","",NETWORKDAYS(U20,W20)) -> 3 | Y20: =IF(W20="","",NETWORKDAYS(N20,W20)) -> 18 | Z20: =IF(Y20="","",IF(Y20<=20,"EFICIENTE","NO EFICIENTE")) -> EFICIENTE | AA20: TERMINADO | AB20: IMPORTIZ | AC20: 30.16 | AD20: 4 | AE20: 24 | AF20: =ROUNDUP((F20*1/(AC20*AD20*M20*AE20)),0) -> 4 | AG20: =67/24 -> 2.7916667 | AH20: =WORKDAY.INTL(P20,AF20,1,0) -> 46269
A21: OP21 22 AGOS | B21: CORDON TELAR TUBULAR PLANO POLIESTER 14MM | C21: KY#19 | D21: CORDON | E21: CLAUDIO | F21: =5000+5000 -> 10000 | G21: 7995 | H21: 4792 | I21: =1448+1213 -> 2661 | J21: 227 | K21: 6.59 | L21: =+J21/G21 -> 0.028392745 | M21: 0.98 | N21: 46239 | O21: 46240 | P21: 46258 | Q21: 46246 | R21: =IF(Q21="","",NETWORKDAYS(N21,Q21)) -> 6 | S21: 46266 | T21: =IF(S21="","",NETWORKDAYS(Q21,S21)) -> 15 | U21: 46266 | V21: =IF(U21="","",NETWORKDAYS(S21,U21)) -> 1 | W21: 46266 | X21: =IF(W21="","",NETWORKDAYS(U21,W21)) -> 1 | Y21: =IF(W21="","",NETWORKDAYS(N21,W21)) -> 20 | Z21: =IF(Y21="","",IF(Y21<=20,"EFICIENTE","NO EFICIENTE")) -> EFICIENTE | AA21: TERMINADO | AB21: GUAMAN DANILO+STOCK | AC21: 24.96 | AD21: 6 | AE21: 24 | AF21: =ROUNDUP((F21*1/(AC21*AD21*M21*AE21)),0) -> 3 | AG21: =122/24 -> 5.0833333 | AH21: =WORKDAY.INTL(P21,AF21,1,0) -> 46261 | AI21: SE QUEDO 1 DIA PARADA POR MOTIVO DE CARRETO SE VOLVIO A URDIR SE HACIA MOTA COLOR AZUL MARINO
A22: OP52 AGOS | B22: REATA SANDALIA TUBULAR 25MM | C22: JAQ#3 | D22: REATA | E22: CLAUDIO | F22: 3000 | G22: 4682 | H22: 4500 | I22: =41+29 -> 70 | J22: 149 | K22: 255 | L22: =+J22/G22 -> 0.031824007 | M22: 0.71 | N22: 46252 | O22: 46254 | P22: 46265 | Q22: 46261 | R22: =IF(Q22="","",NETWORKDAYS(N22,Q22)) -> 8 | S22: 46272 | T22: =IF(S22="","",NETWORKDAYS(Q22,S22)) -> 8 | U22: 46272 | V22: =IF(U22="","",NETWORKDAYS(S22,U22)) -> 1 | W22: 46273 | X22: =IF(W22="","",NETWORKDAYS(U22,W22)) -> 2 | Y22: =IF(W22="","",NETWORKDAYS(N22,W22)) -> 16 | Z22: =IF(Y22="","",IF(Y22<=20,"EFICIENTE","NO EFICIENTE")) -> EFICIENTE | AA22: TERMINADO | AB22: IVAN ALFONSO | AC22: 26.88 | AD22: 4 | AE22: 24 | AF22: =ROUNDUP((F22*1/(AC22*AD22*M22*AE22)),0) -> 2 | AH22: =WORKDAY.INTL(P22,AF22,1,0) -> 46267
A23: OP61 JUN | B23: ELASTICO CONFECCION BOXER NEGRO /GRIS PERLA | C23: JAQ#18 | D23: ELASTICO | E23: CLAUDIO | F23: 14000 | G23: 4699 | L23: =+J23/G23 -> 0 | M23: 0.82 | N23: 46199 | O23: 46199 | P23: 46199 | Q23: 46239 | R23: =IF(Q23="","",NETWORKDAYS(N23,Q23)) -> 29 | S23: 46255 | T23: =IF(S23="","",NETWORKDAYS(Q23,S23)) -> 13 | V23: =IF(U23="","",NETWORKDAYS(S23,U23)) | X23: =IF(W23="","",NETWORKDAYS(U23,W23)) | Y23: =IF(W23="","",NETWORKDAYS(N23,W23)) | Z23: =IF(AG23="","",IF(AG23<=AF23,"EFICIENTE","NO EFICIENTE")) -> EFICIENTE | AA23: ACABADOS | AB23: BOSTON | AC23: 13.2 | AD23: 6 | AE23: 24 | AF23: =ROUNDUP((F23*1/(AC23*AD23*M23*AE23)),0) -> 9 | AG23: 8 | AH23: =WORKDAY.INTL(P23,AF23,1,0) -> 46212
A24: OP63 JUN | B24: ELASTICO BOSTON NEGRO/GRIS PERLA | C24: JAQ#19 | D24: ELASTICO | E24: JAVIER | F24: 11000 | G24: 7474 | L24: =+J24/G24 -> 0 | M24: 0.67 | N24: 46199 | O24: 46199 | P24: 46246 | Q24: 46224 | R24: =IF(Q24="","",NETWORKDAYS(N24,Q24)) -> 18 | S24: 46255 | T24: =IF(S24="","",NETWORKDAYS(Q24,S24)) -> 24 | V24: =IF(U24="","",NETWORKDAYS(S24,U24)) | X24: =IF(W24="","",NETWORKDAYS(U24,W24)) | Y24: =IF(W24="","",NETWORKDAYS(N24,W24)) | Z24: =IF(AG24="","",IF(AG24<=AF24,"EFICIENTE","NO EFICIENTE")) -> EFICIENTE | AA24: ACABADOS | AB24: BOSTON | AC24: 13.32 | AD24: 6 | AE24: 24 | AF24: =ROUNDUP((F24*1/(AC24*AD24*M24*AE24)),0) -> 9 | AG24: 8 | AH24: =WORKDAY.INTL(P24,AF24,1,0) -> 46259
A25: OP23 AGOS | B25: ELASTICO BOSTON AZUL MARINO/PLOMO AZULADO | C25: JAQ#9 | D25: ELASTICO | E25: JAVIER | F25: 8000 | G25: 8676 | H25: 7605 | J25: 54 | K25: 3.1 | L25: =+J25/G25 -> 0.0062240664 | M25: 0.65 | N25: 46241 | O25: 46241 | P25: 46251 | Q25: 46245 | R25: =IF(Q25="","",NETWORKDAYS(N25,Q25)) -> 3 | S25: 46259 | T25: =IF(S25="","",NETWORKDAYS(Q25,S25)) -> 11 | U25: 46266 | V25: =IF(U25="","",NETWORKDAYS(S25,U25)) -> 6 | W25: 46266 | X25: =IF(W25="","",NETWORKDAYS(U25,W25)) -> 1 | Y25: =IF(W25="","",NETWORKDAYS(N25,W25)) -> 18 | Z25: =IF(AG25="","",IF(AG25<=AF25,"EFICIENTE","NO EFICIENTE")) -> EFICIENTE | AA25: TERMINADO | AB25: BOSTON | AC25: 14.76 | AD25: 8 | AE25: 24 | AF25: =ROUNDUP((F25*1/(AC25*AD25*M25*AE25)),0) -> 5 | AG25: 5 | AH25: =WORKDAY.INTL(P25,AF25,1,0) -> 46258
A26: OP54 JUN | B26: ELASTICO BOSTON VERDE BOTELLA/GRIS PERLA | C26: JAQ#8 | D26: ELASTICO | E26: JAVIER | F26: 10000 | G26: 13352 | H26: 12357 | J26: 85 | K26: 1.23 | L26: =+J26/G26 -> 0.0063660875 | M26: 0.98 | N26: 46199 | O26: 46175 | P26: 46255 | Q26: 46254 | R26: =IF(Q26="","",NETWORKDAYS(N26,Q26)) -> 40 | S26: 46262 | T26: =IF(S26="","",NETWORKDAYS(Q26,S26)) -> 7 | U26: 46265 | V26: =IF(U26="","",NETWORKDAYS(S26,U26)) -> 2 | W26: 46265 | X26: =IF(W26="","",NETWORKDAYS(U26,W26)) -> 1 | Y26: =IF(W26="","",NETWORKDAYS(N26,W26)) -> 47 | Z26: =IF(AG26="","",IF(AG26<=AF26,"EFICIENTE","NO EFICIENTE")) -> EFICIENTE | AA26: TERMINADO | AB26: BOSTON | AC26: 13.56 | AD26: 8 | AE26: 24 | AF26: =ROUNDUP((F26*1/(AC26*AD26*M26*AE26)),0) -> 4 | AG26: 4 | AH26: =WORKDAY.INTL(P26,AF26,1,0) -> 46261 | AI26: MAQUINA CON ORDENES ANTERIORES EN ESPERA QUE SE TERMINE RETRASA ESTA ORDEN
A27: OP43 MAR | B27: ELASTICO CONFECCION BOXER BOSTON | C27: JAQ#2 | D27: ELASTICO | E27: JAVIER | F27: 8000 | G27: 7854 | H27: 7361 | J27: 153.24 | K27: 2.61 | L27: =+J27/G27 -> 0.019511077 | M27: 0.77 | N27: 46076 | O27: 46078 | P27: 46245 | Q27: 46118 | R27: =IF(Q27="","",NETWORKDAYS(N27,Q27)) -> 31 | S27: 46254 | T27: =IF(S27="","",NETWORKDAYS(Q27,S27)) -> 99 | U27: 46260 | V27: =IF(U27="","",NETWORKDAYS(S27,U27)) -> 5 | W27: 46260 | X27: =IF(W27="","",NETWORKDAYS(U27,W27)) -> 1 | Y27: =IF(W27="","",NETWORKDAYS(N27,W27)) -> 133 | Z27: =IF(AG27="","",IF(AG27<=AF27,"EFICIENTE","NO EFICIENTE")) -> EFICIENTE | AA27: TERMINADO | AB27: BOSTON | AC27: 14.88 | AD27: 6 | AE27: 24 | AF27: =ROUNDUP((F27*1/(AC27*AD27*M27*AE27)),0) -> 5 | AG27: 5 | AH27: =WORKDAY.INTL(P27,AF27,1,0) -> 46252 | AI27: MAQUINA CON ORDENES ANTERIORES EN ESPERA QUE SE TERMINE RETRASA ESTA ORDEN
A28: OP23 JUN | B28: REATA SANDALIA EMPALMADA FRANJA CENTRAL LUREX 20MM | C28: KY#12 | D28: REATA | E28: OSCAR | F28: 6000 | G28: 4713 | H28: 4600 | I28: - | J28: 521 | K28: 16.46 | L28: =+J28/G28 -> 0.1105453 | M28: 0.62 | N28: 46177 | O28: 46177 | P28: 46178 | Q28: 46241 | R28: =IF(Q28="","",NETWORKDAYS(N28,Q28)) -> 47 | S28: 46247 | T28: =IF(S28="","",NETWORKDAYS(Q28,S28)) -> 5 | U28: 46251 | V28: =IF(U28="","",NETWORKDAYS(S28,U28)) -> 3 | W28: 46251 | X28: =IF(W28="","",NETWORKDAYS(U28,W28)) -> 1 | Y28: =IF(W28="","",NETWORKDAYS(N28,W28)) -> 53 | Z28: =IF(Y28="","",IF(Y28<=20,"EFICIENTE","NO EFICIENTE")) -> NO EFICIENTE | AA28: TERMINADO | AB28: IMPORTIZ | AC28: 34.8 | AD28: 4 | AE28: 24 | AF28: =ROUNDUP((F28*1/(AC28*AD28*M28*AE28)),0) -> 3 | AG28: 3 | AH28: =WORKDAY.INTL(P28,AF28,1,0) -> 46183 | AI28: RETRASO EN EL URDIDO SE ESTABAN URDIENDO MAS ORDENES DE IMPORTIS
A29: OP24 JUL | B29: REATA ZAPATO TAFETA GRUESA REFLECTIVO 12MM | C29: JAQ#5 | D29: REATA | E29: CLAUDIO | F29: 1500 | G29: 1333 | H29: 1300 | I29: 35 | J29: 128 | K29: 1 | L29: =+J29/G29 -> 0.096024006 | M29: 0.8 | N29: 46216 | O29: 46216 | P29: 46224 | Q29: 46238 | R29: =IF(Q29="","",NETWORKDAYS(N29,Q29)) -> 17 | S29: 46245 | T29: =IF(S29="","",NETWORKDAYS(Q29,S29)) -> 6 | U29: 46247 | V29: =IF(U29="","",NETWORKDAYS(S29,U29)) -> 3 | W29: 46252 | X29: =IF(W29="","",NETWORKDAYS(U29,W29)) -> 4 | Y29: =IF(W29="","",NETWORKDAYS(N29,W29)) -> 27 | Z29: =IF(Y29="","",IF(Y29<=20,"EFICIENTE","NO EFICIENTE")) -> NO EFICIENTE | AA29: TERMINADO | AB29: NUNEZ SANTIAGO | AC29: 41.88 | AD29: 4 | AE29: 24 | AF29: =ROUNDUP((F29*1/(AC29*AD29*M29*AE29)),0) -> 1 | AG29: =8.5/11 -> 0.77272727 | AH29: =WORKDAY.INTL(P29,AF29,1,0) -> 46225 | AI29: RETRASO EN EL URDIDO Y CALIBRACION TIEMPO MUERTO EN CALIBRACION 2 DIAS DESPUES DE MONTAR MAQUIINA
A30: OP18 JUL | B30: ELASTICO CONFECCION REFORZADO PES 50MM FUCSIA / AMARILLO | C30: KY#11 | D30: ELASTICO | E30: JAVIER | F30: 3680 | G30: 3572 | H30: 3404 | I30: 30 | J30: 357 | K30: 11.65 | L30: =+J30/G30 -> 0.099944009 | M30: 0.86 | N30: 46213 | O30: 46213 | P30: 46234 | Q30: 46226 | R30: =IF(Q30="","",NETWORKDAYS(N30,Q30)) -> 10 | S30: 46239 | T30: =IF(S30="","",NETWORKDAYS(Q30,S30)) -> 10 | U30: 46251 | V30: =IF(U30="","",NETWORKDAYS(S30,U30)) -> 9 | W30: 46253 | X30: =IF(W30="","",NETWORKDAYS(U30,W30)) -> 3 | Y30: =IF(W30="","",NETWORKDAYS(N30,W30)) -> 29 | Z30: =IF(Y30="","",IF(Y30<=20,"EFICIENTE","NO EFICIENTE")) -> NO EFICIENTE | AA30: TERMINADO | AB30: GAMBOA | AC30: 16.8 | AD30: 6 | AE30: 24 | AF30: =ROUNDUP((F30*1/(AC30*AD30*M30*AE30)),0) -> 2 | AG30: =76/24 -> 3.1666667 | AH30: =WORKDAY.INTL(P30,AF30,1,0) -> 46238 | AI30: SE MANDA UN PARCIL AL CLIENTE Y SE PLANCHA DESPUES | AT30: EFICIENCIA DE MAQUINA
A31: OP38 JUL | B31: ELASTICO CONFECCION FAJAS MEDICAS 25MM | C31: JAQ#13 | D31: ELASTICO | E31: JOSE | F31: 8280 | G31: 6911 | J31: 380 | K31: 7.85 | L31: =+J31/G31 -> 0.054984807 | M31: 0.71 | N31: 46227 | O31: 46227 | P31: 46238 | Q31: 46234 | R31: =IF(Q31="","",NETWORKDAYS(N31,Q31)) -> 6 | S31: 46253 | T31: =IF(S31="","",NETWORKDAYS(Q31,S31)) -> 14 | U31: 46255 | V31: =IF(U31="","",NETWORKDAYS(S31,U31)) -> 3 | W31: 46259 | X31: =IF(W31="","",NETWORKDAYS(U31,W31)) -> 3 | Y31: =IF(W31="","",NETWORKDAYS(N31,W31)) -> 23 | Z31: =IF(Y31="","",IF(Y31<=20,"EFICIENTE","NO EFICIENTE")) -> NO EFICIENTE | AA31: TERMINADO | AB31: BUENANO + STOCK | AC31: 19.44 | AD31: 6 | AE31: 24 | AF31: =ROUNDUP((F31*1/(AC31*AD31*M31*AE31)),0) -> 5 | AH31: =WORKDAY.INTL(P31,AF31,1,0) -> 46245 | AI31: MAQUINA CON CARGA DE TRABAJO | AT31: ANARANJADO | AU31: 2
A32: OP01 JUL | B32: REATA CONFECCION ZARGA COLCHON | C32: KY#7 | D32: REATA | E32: JOSE | F32: 20000 | G32: 20433 | H32: 19000 | I32: - | J32: 699 | K32: 6.29 | L32: =+J32/G32 -> 0.034209367 | M32: 0.94 | N32: 46206 | O32: 46206 | P32: 46245 | Q32: 46220 | R32: =IF(Q32="","",NETWORKDAYS(N32,Q32)) -> 11 | S32: 46247 | T32: =IF(S32="","",NETWORKDAYS(Q32,S32)) -> 20 | U32: 46253 | V32: =IF(U32="","",NETWORKDAYS(S32,U32)) -> 5 | W32: 46254 | X32: =IF(W32="","",NETWORKDAYS(U32,W32)) -> 2 | Y32: =IF(W32="","",NETWORKDAYS(N32,W32)) -> 35 | Z32: =IF(Y32="","",IF(Y32<=20,"EFICIENTE","NO EFICIENTE")) -> NO EFICIENTE | AA32: TERMINADO | AB32: SICORMATRESS | AC32: 56.04 | AD32: 6 | AE32: 24 | AF32: =ROUNDUP((F32*1/(AC32*AD32*M32*AE32)),0) -> 3 | AG32: =86/24 -> 3.5833333 | AH32: =WORKDAY.INTL(P32,AF32,1,0) -> 46248 | AI32: MAQUINA SE QUEDA PARADA 2 SEMANAS POR QUE NO HABIA TRAMA COLOR PISTACHO
A33: OP06 JUL | B33: REATA SANDALIA EMPALMADA GRUESA 2 CANALES 30MM | C33: KY15 | D33: REATA | E33: OSCAR | F33: 6000 | G33: 5723 | H33: 5875 | J33: 171 | K33: 7.57 | L33: =+J33/G33 -> 0.029879434 | M33: 0.66 | N33: 46206 | O33: 46206 | P33: 46240 | Q33: 46240 | R33: =IF(Q33="","",NETWORKDAYS(N33,Q33)) -> 25 | S33: 46248 | T33: =IF(S33="","",NETWORKDAYS(Q33,S33)) -> 7 | U33: 46248 | V33: =IF(U33="","",NETWORKDAYS(S33,U33)) -> 1 | W33: 46254 | X33: =IF(W33="","",NETWORKDAYS(U33,W33)) -> 5 | Y33: =IF(W33="","",NETWORKDAYS(N33,W33)) -> 35 | Z33: =IF(Y33="","",IF(Y33<=20,"EFICIENTE","NO EFICIENTE")) -> NO EFICIENTE | AA33: TERMINADO | AB33: IMPORTIZ | AC33: 38.16 | AD33: 4 | AE33: 24 | AF33: =ROUNDUP((F33*1/(AC33*AD33*M33*AE33)),0) -> 3 | AG33: =45.5/24 -> 1.8958333 | AH33: =WORKDAY.INTL(P33,AF33,1,0) -> 46245 | AI33: RETRASO EN EL URDIDO Y SE PARA MAQUINA CADA RATO EL ALMA SE ENREDBA
A34: OP08 JUL | B34: REATA SANDALIA TUBULAR GRUES 2 CANALES 30MM | C34: KY15 | D34: REATA | E34: JAVIER | F34: 4000 | G34: 4830 | H34: 3850 | J34: 179 | K34: 7.61 | L34: =+J34/G34 -> 0.037060041 | M34: 0.7 | N34: 46206 | O34: 46206 | P34: 46252 | Q34: 46226 | R34: =IF(Q34="","",NETWORKDAYS(N34,Q34)) -> 15 | S34: 46254 | T34: =IF(S34="","",NETWORKDAYS(Q34,S34)) -> 21 | U34: 46254 | V34: =IF(U34="","",NETWORKDAYS(S34,U34)) -> 1 | W34: 46255 | X34: =IF(W34="","",NETWORKDAYS(U34,W34)) -> 2 | Y34: =IF(W34="","",NETWORKDAYS(N34,W34)) -> 36 | Z34: =IF(Y34="","",IF(Y34<=20,"EFICIENTE","NO EFICIENTE")) -> NO EFICIENTE | AA34: TERMINADO | AB34: IMPORTIZ | AC34: 38.16 | AD34: 4 | AE34: 24 | AF34: =ROUNDUP((F34*1/(AC34*AD34*M34*AE34)),0) -> 2 | AH34: =WORKDAY.INTL(P34,AF34,1,0) -> 46254 | AI34: SE DEMORAN EN EL URDIDO POR MOTIVO QUE NO HABIA MATERIAL
A35: OP24 JUN | B35: REATA SANDALIA EMPALMADA FRANJA CENTRAL LUREX 20MM | C35: KY#12 | D35: REATA | E35: CLAUDIO | F35: 1500 | G35: 1358 | H35: 1375 | I35: 21 | J35: 16 | K35: 0.51 | L35: =+J35/G35 -> 0.011782032 | M35: 0.52 | N35: 46177 | O35: 46177 | P35: 46252 | Q35: 46237 | R35: =IF(Q35="","",NETWORKDAYS(N35,Q35)) -> 43 | S35: 46253 | T35: =IF(S35="","",NETWORKDAYS(Q35,S35)) -> 13 | U35: 46259 | V35: =IF(U35="","",NETWORKDAYS(S35,U35)) -> 5 | W35: 46260 | X35: =IF(W35="","",NETWORKDAYS(U35,W35)) -> 2 | Y35: =IF(W35="","",NETWORKDAYS(N35,W35)) -> 60 | Z35: =IF(Y35="","",IF(Y35<=20,"EFICIENTE","NO EFICIENTE")) -> NO EFICIENTE | AA35: TERMINADO | AB35: IMPORTIZ | AC35: 34.8 | AD35: 2 | AE35: 24 | AF35: =ROUNDUP((F35*1/(AC35*AD35*M35*AE35)),0) -> 2 | AG35: =29/24 -> 1.2083333 | AH35: =WORKDAY.INTL(P35,AF35,1,0) -> 46254 | AI35: URDIDORA CON CARGA DE TRABAJO
A36: OP29 JUN | B36: REATA SANDALIA TUBULAR 25MM | C36: KY#5 | D36: REATA | E36: CARLOS | F36: 3000 | G36: 2900 | H36: 3350 | I36: 31 | J36: 216 | K36: 5.18 | L36: =+J36/G36 -> 0.074482759 | M36: 0.46 | N36: 46177 | O36: 46177 | P36: 46254 | Q36: 46255 | R36: =IF(Q36="","",NETWORKDAYS(N36,Q36)) -> 57 | S36: 46259 | T36: =IF(S36="","",NETWORKDAYS(Q36,S36)) -> 3 | U36: 46260 | V36: =IF(U36="","",NETWORKDAYS(S36,U36)) -> 2 | W36: 46260 | X36: =IF(W36="","",NETWORKDAYS(U36,W36)) -> 1 | Y36: =IF(W36="","",NETWORKDAYS(N36,W36)) -> 60 | Z36: =IF(Y36="","",IF(Y36<=20,"EFICIENTE","NO EFICIENTE")) -> NO EFICIENTE | AA36: TERMINADO | AB36: IMPORTIZ | AC36: 45.72 | AD36: 2 | AE36: 24 | AF36: =ROUNDUP((F36*1/(AC36*AD36*M36*AE36)),0) -> 3 | AG36: =72/24 -> 3 | AH36: =WORKDAY.INTL(P36,AF36,1,0) -> 46259 | AI36: URDIDORA CON CARGA DE TRABAJO
A37: OP10 27-01 JUL | B37: REATA SANDALIA TUBULAR LUREX 25MM | C37: KY#5 | D37: REATA | E37: CARLOS | F37: =2000+1000 -> 3000 | G37: 3600 | H37: 3400 | I37: 42 | J37: 198 | K37: 2.3 | L37: =+J37/G37 -> 0.055 | M37: 0.67 | N37: 46205 | O37: 46205 | P37: 46246 | Q37: 46234 | R37: =IF(Q37="","",NETWORKDAYS(N37,Q37)) -> 22 | S37: 46248 | T37: =IF(S37="","",NETWORKDAYS(Q37,S37)) -> 11 | U37: 46253 | V37: =IF(U37="","",NETWORKDAYS(S37,U37)) -> 4 | W37: 46254 | X37: =IF(W37="","",NETWORKDAYS(U37,W37)) -> 2 | Y37: =IF(W37="","",NETWORKDAYS(N37,W37)) -> 36 | Z37: =IF(Y37="","",IF(Y37<=20,"EFICIENTE","NO EFICIENTE")) -> NO EFICIENTE | AA37: TERMINADO | AB37: ALFONZO/MONTESINOS | AC37: 45.72 | AD37: 4 | AE37: 24 | AF37: =ROUNDUP((F37*1/(AC37*AD37*M37*AE37)),0) -> 2 | AG37: =30/24 -> 1.25 | AH37: =WORKDAY.INTL(P37,AF37,1,0) -> 46248 | AI37: DEMORA EN EL URDIDO URDIDOS EN FILA Y MAQUINA CON CARGA DE TRABAJO
A38: OP15-01 JUL | B38: ELASTICO CONFECCION CROCHET 20 25 MM | C38: KY10 | D38: ELASTICO | E38: JAVIER | F38: =8556+7130 -> 15686 | G38: 14751 | L38: =+J38/G38 -> 0 | M38: 0.91 | N38: 46177 | O38: 46181 | P38: 46252 | Q38: 46258 | R38: =IF(Q38="","",NETWORKDAYS(N38,Q38)) -> 58 | T38: =IF(S38="","",NETWORKDAYS(Q38,S38)) | V38: =IF(U38="","",NETWORKDAYS(S38,U38)) | X38: =IF(W38="","",NETWORKDAYS(U38,W38)) | Y38: =IF(W38="","",NETWORKDAYS(N38,W38)) | Z38: =IF(Y38="","",IF(Y38<=20,"EFICIENTE","NO EFICIENTE")) | AA38: ACABADOS | AB38: NUNEZ SANTIAGO | AC38: 19.08 | AD38: 6 | AE38: 24 | AF38: =ROUNDUP((F38*1/(AC38*AD38*M38*AE38)),0) -> 7 | AH38: =WORKDAY.INTL(P38,AF38,1,0) -> 46261 | AI38: UNA ORDEN ANTERIOR SALIO MENOS POR EL RENDIMIENTO SE VUELVE HACER ORDEN PARA COMPLETAR
A39: OP43 AGOS | B39: ELASTICO BOSTON NEGRO/VERDE FLOURECENTE | C39: JAQ#19 | D39: ELASTICO | E39: JAVIER | F39: 9000 | G39: 10695 | L39: =+J39/G39 -> 0 | M39: 0.71 | N39: 46252 | O39: 46254 | P39: 46261 | Q39: 46259 | R39: =IF(Q39="","",NETWORKDAYS(N39,Q39)) -> 6 | S39: 46273 | T39: =IF(S39="","",NETWORKDAYS(Q39,S39)) -> 11 | V39: =IF(U39="","",NETWORKDAYS(S39,U39)) | X39: =IF(W39="","",NETWORKDAYS(U39,W39)) | Y39: =IF(W39="","",NETWORKDAYS(N39,W39)) | Z39: =IF(Y39="","",IF(Y39<=20,"EFICIENTE","NO EFICIENTE")) | AA39: ACABADOS | AB39: BOSTON | AC39: 13.32 | AD39: 6 | AE39: 24 | AF39: 6 | AG39: =156/24 -> 6.5 | AH39: =WORKDAY.INTL(P39,AF39,1,0) -> 46269
A40: OP42 AGOS | B40: ELASTICO BOSTON NEGRO/VERDE FLOURECENTE | C40: JAQ#18 | D40: ELASTICO | E40: JAVIER | F40: 9000 | G40: 9222 | L40: =+J40/G40 -> 0 | M40: 0.71 | N40: 46252 | O40: 46254 | P40: 46260 | Q40: 46255 | R40: =IF(Q40="","",NETWORKDAYS(N40,Q40)) -> 4 | S40: 46273 | T40: =IF(S40="","",NETWORKDAYS(Q40,S40)) -> 13 | V40: =IF(U40="","",NETWORKDAYS(S40,U40)) | X40: =IF(W40="","",NETWORKDAYS(U40,W40)) | Y40: =IF(W40="","",NETWORKDAYS(N40,W40)) | Z40: =IF(Y40="","",IF(Y40<=20,"EFICIENTE","NO EFICIENTE")) | AA40: ACABADOS | AB40: BOSTON | AC40: 13.2 | AD40: 6 | AE40: 24 | AF40: =ROUNDUP((F40*1/(AC40*AD40*M40*AE40)),0) -> 7 | AG40: =156/24 -> 6.5 | AH40: =WORKDAY.INTL(P40,AF40,1,0) -> 46269
...

Sheet RESUMEN 
C2: CONTROL DE PRODUCCION MES DE AGOSTO
C3: TIEMPO DE ENTREGA
C4: ORDENES TOTALES | D4: ORDENES TERMINADAS | E4: ORDENES EN TEJEDURIA | F4: ACABADOS | G4: EFICIENTES | H4: NO EFICIENTES | I4: CAUSAS NO EFICIENTES
C5: 54 | D5: 32 | E5: 4 | F5: 6 | G5: 26 | H5: 10
AB6: CARGO DE TRABAJO EN URDIDORA | AC6: 6
AB7: DEMORA EN EL PLANCHADO | AC7: 1
AB8: FALTA DE MATERIA PRIMA | AC8: 3
C25: ORDENES NO EFICIENTES
C26: # | D26: ORDENES NO EFICIENTES | G26: #DIAS DE ENTREGA | H26: CLIENTES | I26: DIAS DE DEMORA | J26: CAUSA
C27: OP24 JUL | D27: REATA ZAPATO TAFETA GRUESA REFLECTIVO 12MM | G27: 27 | H27: NUNEZ SANTIAGO | I27: =+G27-20 -> 7 | J27: URDIDORA CON CARGA DE TRABAJO Y CALIBRACION
C28: OP18 JUL | D28: ELASTICO CONFECCION REFORZADO PES 50MM | G28: 29 | H28: GAMBOA | I28: =+G28-20 -> 9 | J28: SE MANDO UN PARCIAL AL CLIENTE Y SE PLANCHA DESPUES
C29: OP38 JUL | D29: ELASTICO CONFECCION FAJAS MEDICAS 25MM | G29: 23 | H29: BUEANO | I29: =+G29-20 -> 3 | J29: MAQUINA CON CARGA DE TRABAJO
C30: OP01 JUL | D30: REATA CONFECCION ZARGA COLCHON | G30: 35 | H30: SICORMATRES | I30: =+G30-20 -> 15 | J30: NO HABIA MATERIAL PARA TRAMA COLOR PISTACHO MAQUINA SE QUEDA PARADA
C31: OP06 JUL | D31: REATA SANDALIA EMPALMADA GRUESA 2 CANALES | G31: 35 | H31: IMPORTIZ | I31: =+G31-20 -> 15 | J31: URDIDORA CON CARGA DE TRABAJO Y TRAMA SE ENRIEDA SE PARA CADA RATO
C32: OP08 JUL | D32: REATA SANDALIA EMPALMADA GRUESA 2 CANALES | G32: 36 | H32: IMPORTIZ | I32: =+G32-20 -> 16 | J32: URDIDORA CON CARGA DE TRABAJO Y NO HABIA MATERIAL
C33: OP24 JUN | D33: REATA SANDALIA EMPALMADA FRANJA CENTRAL LUREX 20MM | G33: 60 | H33: IMPORTIZ | I33: =+G33-20 -> 40 | J33: UNA ORDEN ANTERIOR A ESTA SE QUEDO PARADA PARA CONFIRMAR EL ALMA Y CAUSA QUE ESTA SE RETRASARA MAS Y SE DEMORAN EN URDIR
C34: OP29 JUN | D34: REATA SANDALIA TUBULAR LUREX 25MM | G34: 60 | H34: IMPORTIZ | I34: =+G34-20 -> 40 | J34: UNA ORDEN ANTERIOR A ESTA SE QUEDO PARADA PARA CONFIRMAR EL ALMA Y CAUSA QUE ESTA SE RETRASARA MAS Y SE DEMORAN EN URDIR
C35: OP10 27-01 JUL | D35: REATA SANDALIA TUBULAR LUREX 25MM | G35: 36 | H35: ALFONZO/MONTESINOS | I35: =+G35-20 -> 16 | J35: UNA ORDEN ANTERIOR SEGUIA EN MAQUINA POR LO QUE NO ENTRO A TEJEDURIA RAPIDAMENTE Y URDIDOS EN FILA
C36: OP23 JUN | D36: REATA SANDALIA EMPALMADA FRANJA CENTRAL LUREX 20MM | G36: 53 | H36: IMPORTIZ | I36: =+G36-20 -> 33 | J36: PROBLEMAS EN EL URDIDO CON EL LUREX TURQUEZA SE HACE MUCHAS MOTAS ROTO LOS FILAMENTO
C38: FECHAS DE PROCESO DE CADA AREA
C41: #ORDEN | D41: FECHA DE APROBACION DE PEDIDO | E41: FECHA URDIDO | F41: ENTREGA URDIDO | G41: FECHA TERMINA TEJEDURIA | H41: DIAS TERMINA TEJEDURIA | I41: FECHA FIN ENVOLTURA | J41: DIAS ENVOLTURA | K41: FECHA DE FACTURACION | L41: DIAS | M41: FECHA DE FACTURACION | N41: DIAS DE ENTREGA FINAL | P41: DIAS ESTANDARES | Q41: DIAS REALES
C42: OP24 JUL | D42: 46216 | E42: 46238 | F42: 17 | G42: 46245 | H42: 6 | I42: 46247 | J42: 3 | K42: 46252 | L42: 4 | M42: 46252 | N42: 27
C43: OP18 JUL | D43: 46213 | E43: 46226 | F43: 10 | G43: 46239 | H43: 10 | I43: 46251 | J43: 9 | K43: 46253 | L43: 3 | M43: 46253 | N43: 29 | O43: OP24 JUL | P43: 1 | Q43: 1
C44: OP38 JUL | D44: 46227 | E44: 46234 | F44: 6 | G44: 46253 | H44: 14 | I44: 46255 | J44: 3 | K44: 46259 | L44: 3 | M44: 46259 | N44: 23 | O44: OP18 JUL | P44: 2 | Q44: 2
C45: OP01 JUL | D45: 46206 | E45: 46220 | F45: 11 | G45: 46247 | H45: 20 | I45: 46253 | J45: 5 | K45: 46254 | L45: 2 | M45: 46254 | N45: 35 | O45: OP38 JUL | P45: 5 | Q45: 4.5
C46: OP06 JUL | D46: 46206 | E46: 46240 | F46: 25 | G46: 46248 | H46: 7 | I46: 46248 | J46: 1 | K46: 46254 | L46: 5 | M46: 46254 | N46: 35 | O46: OP01 JUL | P46: 3 | Q46: 3
C47: OP08 JUL | D47: 46206 | E47: 46226 | F47: 15 | G47: 46254 | H47: 21 | I47: 46254 | J47: 1 | K47: 46255 | L47: 2 | M47: 46255 | N47: 36 | O47: OP06 JUL | P47: 3 | Q47: 2
C48: OP24 JUN | D48: 46177 | E48: 46237 | F48: 43 | G48: 46253 | H48: 13 | I48: 46259 | J48: 5 | K48: 46260 | L48: 2 | M48: 46260 | N48: 60 | O48: OP08 JUL | P48: 2 | Q48: 2
C49: OP29 JUN | D49: 46177 | E49: 46255 | F49: 57 | G49: 46259 | H49: 3 | I49: 46260 | J49: 2 | K49: 46260 | L49: 1 | M49: 46260 | N49: 60 | O49: OP24 JUN | P49: 2 | Q49: 2
C50: OP10 27-01 JUL | D50: 46205 | E50: 46234 | F50: 22 | G50: 46248 | H50: 11 | I50: 46253 | J50: 4 | K50: 46254 | L50: 2 | M50: 46254 | N50: 36 | O50: OP29 JUN | P50: 3 | Q50: 3
C51: OP23 JUN | D51: 46177 | E51: 46241 | F51: 47 | G51: 46247 | H51: 5 | I51: 46251 | J51: 3 | M51: 46251 | N51: 53
C52: DE MI FECHA DE APROBACION A MI FECHA DE URDIDO ME DEMORE 17 DIAS | O52: OP10 JUL | P52: 2 | Q52: 1.5
C53: DE MI FECHA DE URDIDO A MI FECHA DE TEJEDURIA ME DEMORE 6 DIAS INCLUYE CALIBRACION Y MONTAJE | K53: 21
C54: DE MI FECHA DE TEJEDURIA A MI FECHA DE ENVOLTURA SON 3 DIAS
C55: DE MI FECHA DE APROBACION A MI FECHA DE FACTURACION SON 27 DIAS
K61: EFICIENCIA DE ENTREGA
K62: NO EFICIENTE | L62: =IF(#REF!="","",NETWORKDAYS(#REF!,#REF!)) -> #REF!
K63: NO EFICIENTE | L63: =IF(#REF!="","",NETWORKDAYS(#REF!,#REF!)) -> #REF!
K64: NO EFICIENTE | L64: =IF(#REF!="","",NETWORKDAYS(#REF!,#REF!)) -> #REF!
K65: NO EFICIENTE | L65: =IF(#REF!="","",NETWORKDAYS(#REF!,#REF!)) -> #REF!
...

Sheet Hoja1
L1: COMPARATIVO
H2: AGOSTO
G3: ORDENES TOTALES | H3: EFICIENTES | I3: NO EFICIENTES | M3: MEJORA
G4: 53 | H4: 26 | I4: 10
S6: Indicador | T6: Julio | U6: Agosto | V6: Mejora
S7: Tiempo de entrega | T7: 0.55 | U7: 0.72 | V7: 🟢 +30%
M8: EN EL TIEMPO DE ENTREGA HA MEJORADO UN 30% | S8: EFICIENTE | T8: 26 | U8: 26
S9: NO EFICIENTE | T9: 21 | U9: 10
S10: Montaje | T10: 327 TIRAS | U10: 317 TIRAS | V10: 🟢-3.15%
S11: Calibración | T11: 55 | U11: 54 | V11: 🟢 -1,85 %
T14: =55*6 -> 330
T15: =T14*1000 -> 330000
T16: =T15/20 -> 16500
T17: =T16/6 -> 2750
T18: =T17/100 -> 27.5

Sheet MONTAJE 
A1: ORDEN | B1: AMPARO | C1: EVELYN | D1: JAVIER | E1: JESSICA | F1: OSCAR | G1: ALEXANDER | H1: CLAUDIO | I1: JOSE
A2: OP40 JUL | D2: 6 | J2: =SUM(D2:I2) -> 6
A3: OP09 JUL | E3: 2 | F3: 2 | J3: =SUM(D3:I3) -> 4
A4: OP36 JUL | B4: 1 | C4: 1 | J4: =SUM(D4:I4) -> 0
A5: OP41 JUL | B5: 1 | C5: 1 | J5: =SUM(D5:I5) -> 0
A6: OP39 JUL | C6: 2 | E6: 2 | J6: =SUM(D6:I6) -> 2
A7: OP20 AGOS | B7: 6 | J7: =SUM(D7:I7) -> 0
A8: OP42 JUL | B8: 2 | C8: 2 | J8: =SUM(D8:I8) -> 0
A9: OP03 04 AGOS | B9: 6 | J9: =SUM(D9:I9) -> 0
A10: OP02 AGOS | B10: 2 | C10: 2 | J10: =SUM(D10:I10) -> 0
A11: OP41 AGOS | C11: 6 | J11: =SUM(D11:I11) -> 0
A12: OP07 AGOS | B12: 3 | E12: 3 | J12: =SUM(D12:I12) -> 3
A13: OP01 AGOS | E13: 2 | J13: =SUM(D13:I13) -> 2
A14: OP37 AGOS | B14: 3 | C14: 3 | J14: =SUM(D14:I14) -> 0
A15: OP23 JUN | B15: 2 | E15: 2 | J15: =SUM(D15:I15) -> 2
A16: OP43 MAR | D16: 3 | E16: 3 | J16: =SUM(D16:I16) -> 6
A17: OP61 JUN | B17: 6 | C17: 6 | J17: =SUM(D17:I17) -> 0
A18: OP63 JUN | D18: 6 | J18: =SUM(D18:I18) -> 6
A19: OP23 AGOS | D19: 8 | J19: =SUM(D19:I19) -> 8
A20: OP24 JUL | B20: 3 | C20: 1 | J20: =SUM(D20:I20) -> 0
A21: OP18 JUL | B21: 3 | G21: 3 | J21: =SUM(D21:I21) -> 3
A22: OP38 JUL | B22: 3 | C22: 3 | J22: =SUM(D22:I22) -> 0
A23: OP01 JUL | H23: 6 | J23: =SUM(D23:I23) -> 6
A24: OP06 JUL | B24: 2 | C24: 2 | J24: =SUM(D24:I24) -> 0
A25: OP08 JUL | B25: 2 | E25: 2 | J25: =SUM(D25:I25) -> 2
A26: OP24 JUN | B26: 4 | J26: =SUM(D26:I26) -> 0
A27: OP29 JUN | B27: 1 | E27: 1 | J27: =SUM(D27:I27) -> 1
A28: OP10 27-01 JUL | B28: 1.5 | C28: 1 | E28: 0.5 | J28: =SUM(D28:I28) -> 0.5
A29: OP21 22 AGOS | B29: 2 | C29: 2 | J29: =SUM(D29:I29) -> 0
A30: OP15-01 JUL | B30: ANUDANDO CAUCHO | C30: 11 | D30: 11 | J30: =SUM(D30:I30) -> 11
A31: OP30 AGOS | B31: 2 | E31: 2 | J31: =SUM(D31:I31) -> 2
A32: OP54 JUN | B32: 2.5 | C32: 1.5 | D32: 4 | J32: =SUM(D32:I32) -> 4
A33: OP33 AGOS | D33: 6 | J33: =SUM(D33:I33) -> 6
A34: OP12 11 AGOS | C34: 6 | J34: =SUM(D34:I34) -> 0
A35: OP24 AGOS | C35: 6 | J35: =SUM(D35:I35) -> 0
A36: OP12 MAY | B36: 2 | C36: 2 | J36: =SUM(D36:I36) -> 0
A37: OP43 AGOS | D37: 6 | J37: =SUM(D37:I37) -> 6
A38: OP42 AGOS | D38: 2.5 | F38: 3.5 | J38: =SUM(D38:I38) -> 6
A39: OP32 AGOS | D39: 2 | E39: 0.5 | F39: 3.5 | J39: =SUM(D39:I39) -> 6
A40: OP17-01JUN | B40: 2 | J40: =SUM(D40:I40) -> 0
...

Sheet CALIBRACION
A1: CALIBRACION MES DE JULIO
A2: N | B2: NOMBRE | C2: NUMERO DE VECES | D2: ARTICULO | E2: OBSERVACIONES
A3: 1 | B3: CARLOS | C3: =COUNTIF('DATOS GENERALES '!E:E,CALIBRACION!B3) -> 7 | D3: REATAS
A4: 2 | B4: OSCAR | C4: =COUNTIF('DATOS GENERALES '!E:E,CALIBRACION!B4) -> 10 | D4: 2 CORDON, 2 ELASTICOS, 7 REATAS
A5: 3 | B5: JOSE | C5: =COUNTIF('DATOS GENERALES '!E:E,CALIBRACION!B5) -> 8 | D5: 4 ELASTICOS, 3 REATAS, 1 CORDON
A6: 4 | B6: CLAUDIO | C6: =COUNTIF('DATOS GENERALES '!E:E,CALIBRACION!B6) -> 15 | D6: 9 REATAS, 2 ELASTICOS, 2 CORDON
A7: 5 | B7: JAVIER | C7: =COUNTIF('DATOS GENERALES '!E:E,CALIBRACION!B7) -> 14 | D7: 4 REATAS, 10 ELASTICOS
A8: 6 | B8: JESSICA | C8: =COUNTIF('DATOS GENERALES '!E:E,CALIBRACION!B8) -> 1 | D8: 1 REATA, 1 ELASTICO
A9: TOTAL | C9: =SUM(C3:C8) -> 55
