Workbook

Sheet DATOS GENERALES
Q1: URDIDO | S1: PRODUCCION | U1: ENVOLTURA | W1: FACTURACION
A2: ORDENES DE PRODUCCION JULIO | B2: DETALLE | C2: MAQUINA | D2: PRODUCTO | E2: CALIBRACION | F2: MTS PEDIDO | G2: MTS PRODUCCION | H2: MTS FACRURADOS | I2: STOCK | J2: MTS FALLA | K2: KG DE FALLA | L2: % FALLA | M2: EFICIENCIA MAQUINA | N2: INGRESO | O2: APROBACION | P2: INICIO PRODUCCION | Q2: FECHA URDIDO | R2: DIAS | S2: FIN PRODUCCION | T2: DIAS | U2: FECHA FIN ENVOLTURA | V2: DIAS | W2: FECHA DE FACTURACION | X2: DIAS | Y2: DIAS TOTAL | Z2: EFICIENCIA DE ENTREGA | AA2: ESTADO | AB2: CLIENTE | AC2: MTS X HORA | AD2: COLOR | AE2: DIAS ESTIMADOS DE PRODUCCION | AF2: DIAS REALES DE PRODUCCION | AG2: OBSERVACIONES
A3: OP36 JUN | B3: ELASTICO ZAPATO REFORZADO 10MM APRESTO | C3: JAQ#4 | D3: REATA | E3: JAVIER | F3: 2760 | G3: 3420 | H3: 3312 | I3: - | J3: 376 | K3: 2.87 | L3: =+J3/G3 -> 0.10994152 | M3: 0.8 | N3: 46192 | O3: 46192 | P3: 46192 | Q3: 46199 | R3: =IF(Q3="","",NETWORKDAYS(N3,Q3)) -> 6 | S3: 46211 | T3: =IF(S3="","",NETWORKDAYS(Q3,S3)) -> 9 | U3: 46216 | V3: =IF(U3="","",NETWORKDAYS(S3,U3)) -> 4 | W3: 46216 | X3: =IF(W3="","",NETWORKDAYS(U3,W3)) -> 1 | Y3: =IF(W3="","",NETWORKDAYS(N3,W3)) -> 17 | Z3: =IF(Y3="","",IF(Y3<=20,"EFICIENTE","NO EFICIENTE")) -> EFICIENTE | AA3: TERMINADO | AB3: MATUTE +STOCK | AC3: 18.36 | AD3: BLANCO/BEIGE/MELON/NEGRO | AE3: =(((F3)/((AC3*10*6)+(AC3*12*6)))) -> 1.1388394 | AF3: 1.33 | AG3: ARREGLANDO CAUCHOS /ARREGLANDO TIRS TORCIDAS
A4: OP38 JUN | B4: REATA CONFECCION EMPALMADA DELGADA 7MM | C4: KY#6 | D4: REATA | E4: JAVIER | F4: 12000 | G4: 11740 | H4: 11700 | I4: - | J4: 87 | K4: 0.65 | L4: =+J4/G4 -> 0.0074105622 | M4: 0.82 | N4: 46192 | O4: 46192 | P4: 46192 | Q4: 46202 | R4: =IF(Q4="","",NETWORKDAYS(N4,Q4)) -> 7 | S4: 46210 | T4: =IF(S4="","",NETWORKDAYS(Q4,S4)) -> 7 | U4: 46211 | V4: =IF(U4="","",NETWORKDAYS(S4,U4)) -> 2 | W4: 46212 | X4: =IF(W4="","",NETWORKDAYS(U4,W4)) -> 2 | Y4: =IF(W4="","",NETWORKDAYS(N4,W4)) -> 15 | Z4: =IF(Y4="","",IF(Y4<=20,"EFICIENTE","NO EFICIENTE")) -> EFICIENTE | AA4: TERMINADO | AB4: FAME | AC4: 64.92 | AE4: =(((F4)/((AC4*10*6)+(AC4*12*6)))) -> 1.4003249 | AF4: 1.54
A5: OP15 JUN | B5: REATA SANDALIA EMPALMADA COCIDO CENTRAL 30MM | C5: KY#14 | D5: REATA | E5: JAVIER | F5: 6000 | G5: 6648 | H5: 6625 | I5: - | J5: 220 | K5: 4.62 | L5: =+J5/G5 -> 0.033092659 | M5: 0.8 | N5: 46204 | O5: 46204 | P5: 46204 | Q5: 46206 | R5: =IF(Q5="","",NETWORKDAYS(N5,Q5)) -> 3 | S5: 46216 | T5: =IF(S5="","",NETWORKDAYS(Q5,S5)) -> 7 | U5: 46217 | V5: =IF(U5="","",NETWORKDAYS(S5,U5)) -> 2 | W5: 46218 | X5: =IF(W5="","",NETWORKDAYS(U5,W5)) -> 2 | Y5: =IF(W5="","",NETWORKDAYS(N5,W5)) -> 11 | Z5: =IF(Y5="","",IF(Y5<=45,"EFICIENTE","NO EFICIENTE")) -> EFICIENTE | AA5: TERMINADO | AB5: IMPORTIZ | AC5: 28.2 | AD5: NEGRO/AZUL MARINO/CAFÉ | AE5: =(((F5)/((AC5*10*4)+(AC5*12*4)))) -> 2.417795 | AF5: 3.04
A6: OP05 JUL | B6: RETA CONFECCION EMPALMDA DELGADA 7MM | C6: KY#6 | D6: REATA | E6: JAVIER | F6: 6000 | G6: 4459 | H6: 4400 | I6: 85 | J6: 18 | K6: 0.13 | L6: =+J6/G6 -> 0.0040367795 | M6: 0.82 | N6: 46206 | O6: 46206 | P6: 46206 | Q6: 46211 | R6: =IF(Q6="","",NETWORKDAYS(N6,Q6)) -> 4 | S6: 46213 | T6: =IF(S6="","",NETWORKDAYS(Q6,S6)) -> 3 | U6: 46217 | V6: =IF(U6="","",NETWORKDAYS(S6,U6)) -> 3 | W6: 46219 | X6: =IF(W6="","",NETWORKDAYS(U6,W6)) -> 3 | Y6: =IF(W6="","",NETWORKDAYS(N6,W6)) -> 10 | Z6: =IF(Y6="","",IF(Y6<=20,"EFICIENTE","NO EFICIENTE")) -> EFICIENTE | AA6: TERMINADO | AB6: FAME | AC6: 64.8 | AD6: BEIGE | AE6: =(((F6)/((AC6*10*6)+(AC6*12*6)))) -> 0.70145903 | AF6: 1.36
A7: OP49 JUN | B7: REATA CONFECCION EMPALMADA 10MM | C7: KY#17 | D7: REATA | E7: CLAUDIO | F7: 15000 | G7: 16428 | H7: 6800 | I7: - | J7: 168 | K7: 1.28 | L7: =+J7/G7 -> 0.010226443 | M7: 0.8 | N7: 46197 | O7: 46197 | P7: 46197 | Q7: 46204 | R7: =IF(Q7="","",NETWORKDAYS(N7,Q7)) -> 6 | S7: 46211 | T7: =IF(S7="","",NETWORKDAYS(Q7,S7)) -> 6 | U7: 46213 | V7: =IF(U7="","",NETWORKDAYS(S7,U7)) -> 3 | W7: 46204 | X7: =IF(W7="","",NETWORKDAYS(U7,W7)) -> -8 | Y7: =IF(W7="","",NETWORKDAYS(N7,W7)) -> 6 | Z7: =IF(Y7="","",IF(Y7<=20,"EFICIENTE","NO EFICIENTE")) -> EFICIENTE | AA7: TERMINADO | AB7: IMTEXMEL | AC7: 76.92 | AD7: CRUDO | AE7: =(((F7)/((AC7*10*6)+(AC7*12*6)))) -> 1.4773318 | AF7: 1.71
A8: OP46 47 JUN | B8: REATA CONFECCION EMPALMDA PES 10MM | C8: KY#2 | D8: REATA | E8: OSCAR | F8: 4000 | G8: 3745 | H8: 3600 | I8: 73 | J8: 287 | K8: 4.55 | L8: =+J8/G8 -> 0.076635514 | M8: 0.8 | N8: 46199 | O8: 46199 | P8: 46199 | Q8: 46212 | R8: =IF(Q8="","",NETWORKDAYS(N8,Q8)) -> 10 | S8: 46217 | T8: =IF(S8="","",NETWORKDAYS(Q8,S8)) -> 4 | U8: 46219 | V8: =IF(U8="","",NETWORKDAYS(S8,U8)) -> 3 | W8: 46224 | X8: =IF(W8="","",NETWORKDAYS(U8,W8)) -> 4 | Y8: =IF(W8="","",NETWORKDAYS(N8,W8)) -> 18 | Z8: =IF(Y8="","",IF(Y8<=20,"EFICIENTE","NO EFICIENTE")) -> EFICIENTE | AA8: TERMINADO | AB8: RAMOS /NUÑEZ | AC8: 48.96 | AD8: AZUL MARINO PLOMO/BLANCO | AE8: =(((F8)/((AC8*10*4)+(AC8*12*4)))) -> 0.92840166 | AF8: 1.45
A9: OP59 JUN | B9: REATA ZAPATO TAFETA DELGADA 20MM | C9: JAQ#11 | D9: REATA | E9: CARLOS | F9: 6600 | G9: 5284 | H9: 5450 | I9: - | J9: 1049 | K9: 4.72 | L9: =+J9/G9 -> 0.19852385 | M9: 0.81 | N9: 46198 | O9: 46203 | P9: 46203 | Q9: 46210 | R9: =IF(Q9="","",NETWORKDAYS(N9,Q9)) -> 9 | S9: 46216 | T9: =IF(S9="","",NETWORKDAYS(Q9,S9)) -> 5 | U9: 46217 | V9: =IF(U9="","",NETWORKDAYS(S9,U9)) -> 2 | W9: 46220 | X9: =IF(W9="","",NETWORKDAYS(U9,W9)) -> 4 | Y9: =IF(W9="","",NETWORKDAYS(N9,W9)) -> 17 | Z9: =IF(Y9="","",IF(Y9<=20,"EFICIENTE","NO EFICIENTE")) -> EFICIENTE | AA9: TERMINADO | AB9: FAME+STOCK | AC9: 37.92 | AD9: PATUCA | AE9: =(((F9)/((AC9*10*6)+(AC9*12*6)))) -> 1.3185654 | AF9: 0.95
A10: OP58 JUN | B10: CORDON TELAR TUBULAR PLANO POLIESTER 14MM | C10: KY#11 | D10: CORDON | E10: JOSE | F10: 10800 | G10: 11331 | H10: 9340 | I10: - | J10: 65 | K10: 1.55 | L10: =+J10/G10 -> 0.0057364752 | M10: 0.8 | N10: 46203 | O10: 46203 | P10: 46203 | Q10: 46211 | R10: =IF(Q10="","",NETWORKDAYS(N10,Q10)) -> 7 | S10: 46223 | T10: =IF(S10="","",NETWORKDAYS(Q10,S10)) -> 9 | U10: 46225 | V10: =IF(U10="","",NETWORKDAYS(S10,U10)) -> 3 | W10: 46225 | X10: =IF(W10="","",NETWORKDAYS(U10,W10)) -> 1 | Y10: =IF(W10="","",NETWORKDAYS(N10,W10)) -> 17 | Z10: =IF(Y10="","",IF(Y10<=20,"EFICIENTE","NO EFICIENTE")) -> EFICIENTE | AA10: TERMINADO | AB10: CHICAIZA RODRIGUEZ CARMEN ABELINA SANI | AC10: 30.24 | AD10: BLANCO CRUDO NEGRO | AE10: =(((F10)/((AC10*10*6)+(AC10*12*6)))) -> 2.7056277 | AF10: 3.5
A11: OP48 JUN | B11: REATA CONFECCION EMPALMADA 20MM | C11: KY#2 | D11: REATA | E11: OSCAR | F11: 4000 | G11: 3734 | H11: 3150 | I11: - | M11: 0.97 | N11: 46198 | O11: 46198 | P11: 46199 | Q11: 46211 | R11: =IF(Q11="","",NETWORKDAYS(N11,Q11)) -> 10 | S11: 46224 | T11: =IF(S11="","",NETWORKDAYS(Q11,S11)) -> 10 | U11: 46225 | V11: =IF(U11="","",NETWORKDAYS(S11,U11)) -> 2 | W11: 46225 | X11: =IF(W11="","",NETWORKDAYS(U11,W11)) -> 1 | Y11: =IF(W11="","",NETWORKDAYS(N11,W11)) -> 20 | Z11: =IF(Y11="","",IF(Y11<=20,"EFICIENTE","NO EFICIENTE")) -> EFICIENTE | AA11: TERMINADO | AB11: RAMOS HARO EDWIN ERNAN NUNEZ ACOSTA RAUL SANTIAGO | AC11: 48.96 | AD11: NEGRO/BLANCO/BLANCO NEGRO | AE11: =(((F11)/((AC11*10*4)+(AC11*12*4)))) -> 0.92840166 | AF11: 0.81
A12: OP11 12 JUL | B12: REATA ZAPATO TAFETA DELGADA 10 15 MM | C12: KY#17 | D12: REATA | E12: CLAUDIO | F12: =6000+3000 -> 9000 | G12: 8469 | H12: 8100 | I12: - | J12: 415 | K12: 1.62 | L12: =+J12/G12 -> 0.049002243 | M12: 0.82 | N12: 46203 | O12: 46204 | P12: 46206 | Q12: 46218 | R12: =IF(Q12="","",NETWORKDAYS(N12,Q12)) -> 12 | S12: 46225 | T12: =IF(S12="","",NETWORKDAYS(Q12,S12)) -> 6 | U12: 46226 | V12: =IF(U12="","",NETWORKDAYS(S12,U12)) -> 2 | W12: 46226 | X12: =IF(W12="","",NETWORKDAYS(U12,W12)) -> 1 | Y12: =IF(W12="","",NETWORKDAYS(N12,W12)) -> 18 | Z12: =IF(Y12="","",IF(Y12<=20,"EFICIENTE","NO EFICIENTE")) -> EFICIENTE | AA12: TERMINADO | AB12: NUNES SANTIAGO | AC12: 81 | AD12: VARIOS | AE12: =(((F12)/((AC12*10*6)+(AC12*12*6)))) -> 0.84175084 | AF12: 0.75
A13: OP02 JUL | B13: REATA SANDALIA GRUESA 15MM | C13: JAQ11 | D13: REATA | E13: OSCAR | F13: 6000 | G13: 5805 | H13: 5500 | I13: - | J13: 226 | K13: 1.1 | L13: =+J13/G13 -> 0.038931955 | M13: 0.9 | N13: 46206 | O13: 46206 | P13: 46206 | Q13: 46223 | R13: =IF(Q13="","",NETWORKDAYS(N13,Q13)) -> 12 | S13: 46230 | T13: =IF(S13="","",NETWORKDAYS(Q13,S13)) -> 6 | U13: 46231 | V13: =IF(U13="","",NETWORKDAYS(S13,U13)) -> 2 | W13: 46231 | X13: =IF(W13="","",NETWORKDAYS(U13,W13)) -> 1 | Y13: =IF(W13="","",NETWORKDAYS(N13,W13)) -> 18 | Z13: =IF(Y13="","",IF(Y13<=20,"EFICIENTE","NO EFICIENTE")) -> EFICIENTE | AA13: TERMINADO | AB13: COMPANIA LUIGI VALDINI | AC13: 42.6 | AD13: NEGRO/PATCA | AE13: =(((F13)/((AC13*10*6)+(AC13*12*6)))) -> 1.0670081 | AF13: 1.12
A14: OP19 26 JUL | B14: CORDON PLANO ANCHO 160 PP NEGRO / BLANCO | C14: KY6 | D14: CORDON | E14: CARLOS | F14: =32400+16200 -> 48600 | G14: 43897 | H14: - | I14: 43647 | J14: 441 | K14: 3 | L14: =+J14/G14 -> 0.010046245 | M14: 0.97 | N14: 46174 | O14: 46174 | P14: 46178 | Q14: 46224 | R14: =IF(Q14="","",NETWORKDAYS(N14,Q14)) -> 37 | S14: 46231 | T14: =IF(S14="","",NETWORKDAYS(Q14,S14)) -> 6 | U14: 46231 | V14: =IF(U14="","",NETWORKDAYS(S14,U14)) -> 1 | W14: 46189 | X14: =IF(W14="","",NETWORKDAYS(U14,W14)) -> -31 | Y14: =IF(W14="","",NETWORKDAYS(N14,W14)) -> 12 | Z14: =IF(Y14="","",IF(Y14<=20,"EFICIENTE","NO EFICIENTE")) -> EFICIENTE | AA14: TERMINADO | AB14: RICACHI ANGEL+STOCK | AC14: 81.24 | AD14: NEGRO/BLANCO | AE14: =(((F14)/((AC14*10*9)+(AC14*12*9)))) -> 3.0213509 | AF14: 3.29 | AG14: OJO ESTA ORDEN SE MANDO HACER PARA EL CLIENTE Y PARA STOCK
A15: OP29 JUL | B15: CORDON TELAR TUBULAR NYLON JAQUARD | C15: JAQ#7 | D15: CORDON | E15: JESSICA | F15: 4860 | G15: 4749 | H15: - | I15: 4349.6667 | J15: 61 | K15: 2.12 | L15: =+J15/G15 -> 0.012844809 | M15: 0.85 | N15: 46220 | O15: 46220 | P15: 46220 | Q15: 46226 | R15: =IF(Q15="","",NETWORKDAYS(N15,Q15)) -> 5 | S15: 46231 | T15: =IF(S15="","",NETWORKDAYS(Q15,S15)) -> 4 | U15: 46233 | V15: =IF(U15="","",NETWORKDAYS(S15,U15)) -> 3 | W15: 46233 | X15: =IF(W15="","",NETWORKDAYS(U15,W15)) -> 1 | Y15: =IF(W15="","",NETWORKDAYS(N15,W15)) -> 10 | Z15: =IF(Y15="","",IF(Y15<=20,"EFICIENTE","NO EFICIENTE")) -> EFICIENTE | AA15: TERMINADO | AB15: RAMOS EDWIN | AC15: 17.28 | AD15: NEGRO/AZUL MARINO | AE15: =(((F15)/((AC15*10*6)+(AC15*12*6)))) -> 2.1306818 | AF15: 2.25
A16: OP50 JUN | B16: ELASTICO CONFECCION FAJAS MEDICAS NYLON 25MM | C16: JAQ13 | D16: ELASTICO | E16: JAVIER | F16: 8280 | G16: 8978 | H16: 7721 | I16: - | J16: 260 | K16: 2.55 | L16: =+J16/G16 -> 0.028959679 | M16: 0.94 | N16: 46197 | O16: 46199 | P16: 46199 | Q16: 46212 | R16: =IF(Q16="","",NETWORKDAYS(N16,Q16)) -> 12 | S16: 46224 | T16: =IF(S16="","",NETWORKDAYS(Q16,S16)) -> 9 | U16: 46225 | V16: =IF(U16="","",NETWORKDAYS(S16,U16)) -> 2 | W16: 46223 | X16: =IF(W16="","",NETWORKDAYS(U16,W16)) -> -3 | Y16: =IF(W16="","",NETWORKDAYS(N16,W16)) -> 19 | Z16: =IF(Y16="","",IF(Y16<=20,"EFICIENTE","NO EFICIENTE")) -> EFICIENTE | AA16: TERMINADO | AB16: NUÑEZ / BUENANO | AC16: 19.44 | AD16: CRUDO/BLANCO | AE16: =(((F16)/((AC16*10*6)+(AC16*12*6)))) -> 3.2267116 | AF16: 5.83
A17: OP25 30 JUL | B17: CORDON RACHELL | C17: RACHELL | D17: CORDON | E17: JOSE | F17: =9000+5000 -> 14000 | G17: 12464 | H17: 10412 | I17: - | J17: 299 | K17: 2.34 | L17: =+J17/G17 -> 0.023989089 | M17: 0.86 | N17: 46220 | O17: 46220 | P17: 46223 | Q17: 46230 | R17: =IF(Q17="","",NETWORKDAYS(N17,Q17)) -> 7 | S17: 46237 | T17: =IF(S17="","",NETWORKDAYS(Q17,S17)) -> 6 | U17: 46238 | V17: =IF(U17="","",NETWORKDAYS(S17,U17)) -> 2 | W17: 46238 | X17: =IF(W17="","",NETWORKDAYS(U17,W17)) -> 1 | Y17: =IF(W17="","",NETWORKDAYS(N17,W17)) -> 13 | Z17: =IF(Y17="","",IF(Y17<=20,"EFICIENTE","NO EFICIENTE")) -> EFICIENTE | AA17: TERMINADO | AB17: CABEZAS RAMIRES+LALVAY MONICA | AC17: 16.68 | AD17: VARIOS | AE17: =(((F17)/((AC17*10*24)+(AC17*12*24)))) -> 1.5896374 | AF17: 1.62
A18: OP22 JUL | B18: REATA SANDALI TUBULAR OJAL PES FDY 10MM | C18: JAQ#5 | D18: REATA | E18: JESSICA | F18: 3000 | G18: 2866 | H18: 2700 | I18: - | J18: 136 | K18: 0.94 | L18: =+J18/G18 -> 0.047452896 | M18: 0.95 | N18: 46216 | O18: 46216 | P18: 46224 | Q18: 46231 | R18: =IF(Q18="","",NETWORKDAYS(N18,Q18)) -> 12 | S18: 46237 | T18: =IF(S18="","",NETWORKDAYS(Q18,S18)) -> 5 | U18: 46238 | V18: =IF(U18="","",NETWORKDAYS(S18,U18)) -> 2 | W18: 46238 | X18: =IF(W18="","",NETWORKDAYS(U18,W18)) -> 1 | Y18: =IF(W18="","",NETWORKDAYS(N18,W18)) -> 17 | Z18: =IF(Y18="","",IF(Y18<=20,"EFICIENTE","NO EFICIENTE")) -> EFICIENTE | AA18: TERMINADO | AB18: NUNE SANTIAGO | AC18: 41.64 | AD18: NEGRO | AE18: =(((F18)/((AC18*10*4)+(AC36*12*4)))) -> 0.90869439 | AF18: 0.89
A19: OP33 34 JUL | B19: REATA MOCHILA DELGADA 10 15MM | C19: JAQ#10 | D19: REATA | E19: JOSE | F19: =5000+1000 -> 6000 | G19: 6145 | H19: 5979 | I19: - | J19: 116 | K19: 1.45 | L19: =+J19/G19 -> 0.018877136 | M19: 0.8 | N19: 46224 | O19: 46224 | P19: 46225 | Q19: 46233 | R19: =IF(Q19="","",NETWORKDAYS(N19,Q19)) -> 8 | S19: 46238 | T19: =IF(S19="","",NETWORKDAYS(Q19,S19)) -> 4 | U19: 46240 | V19: =IF(U19="","",NETWORKDAYS(S19,U19)) -> 3 | W19: 46240 | X19: =IF(W19="","",NETWORKDAYS(U19,W19)) -> 1 | Y19: =IF(W19="","",NETWORKDAYS(N19,W19)) -> 13 | Z19: =IF(Y19="","",IF(Y19<=20,"EFICIENTE","NO EFICIENTE")) -> EFICIENTE | AA19: TERMINADO | AB19: CRIOLLO CRISTIAN JESUS | AC19: 84 | AD19: VARIOS | AE19: =(((F19)/((AC19*10*4)+(AC41*12*4)))) -> 1.1556953 | AF19: 0.64
A20: OP34 JUN | B20: REATA CONFECCION EMPALMADA 15MM | C20: KY#2 | D20: REATA | E20: CARLOS | F20: 12000 | G20: 111111 | H20: 11950 | I20: 88 | J20: 734 | K20: 4.02 | L20: =+J20/G20 -> 0.0066060066 | M20: 0.87 | N20: 46178 | O20: 46178 | P20: 46179 | Q20: 46199 | R20: =IF(Q20="","",NETWORKDAYS(N20,Q20)) -> 16 | S20: 46211 | T20: =IF(S20="","",NETWORKDAYS(Q20,S20)) -> 9 | U20: 46211 | V20: =IF(U20="","",NETWORKDAYS(S20,U20)) -> 1 | W20: 46216 | X20: =IF(W20="","",NETWORKDAYS(U20,W20)) -> 4 | Y20: =IF(W20="","",NETWORKDAYS(N20,W20)) -> 27 | Z20: =IF(Y20="","",IF(Y20<=32,"EFICIENTE","NO EFICIENTE")) -> EFICIENTE | AA20: TERMINADO | AB20: IMPORTIZ | AC20: 48.96 | AD20: BEIGE | AE20: =(((F20)/((AC20*10*6)+(AC20*12*6)))) -> 1.8568033 | AF20: 1.62 | AG20: SE DEMORAN EN URDIR /URDIDOS EN FILA Y MAQUINA CON CARGA DE TRABAJO
A21: OP07 JUL | B21: REATA SANDALIA TUBULAR GRUESA 2 CANALES 30MM | C21: KY15 | D21: REATA | E21: OSCAR | F21: 6000 | G21: 6152 | H21: 5500 | I21: - | J21: 216 | K21: 915 | L21: =+J21/G21 -> 0.035110533 | M21: 0.8 | N21: 46206 | O21: 46206 | P21: 46206 | Q21: 46227 | R21: =IF(Q21="","",NETWORKDAYS(N21,Q21)) -> 16 | S21: 46237 | T21: =IF(S21="","",NETWORKDAYS(Q21,S21)) -> 7 | U21: 46238 | V21: =IF(U21="","",NETWORKDAYS(S21,U21)) -> 2 | W21: 46238 | X21: =IF(W21="","",NETWORKDAYS(U21,W21)) -> 1 | Y21: =IF(W21="","",NETWORKDAYS(N21,W21)) -> 23 | Z21: =IF(Y21="","",IF(Y21<=24,"EFICIENTE","NO EFICIENTE")) -> EFICIENTE | AA21: TERMINADO | AB21: IMPORTIZ | AC21: 38.16 | AD21: VARIOS | AE21: =(((F21)/((AC21*10*4)+(AC39*12*4)))) -> 2.179219 | AF21: 2.06 | AG21: URDIDO A LA FILA SE DEMORAN EN URDIR
A22: OP26 27 JUN | B22: REATA SANDALIA TUBULAR LUREX 25MM | C22: KY#5 | D22: REATA | E22: CLAUDIO | F22: =2500+2500 -> 5000 | G22: 6441 | H22: 5100 | I22: - | J22: 384 | K22: 9.36 | L22: =+J22/G22 -> 0.059618072 | M22: 0.81 | N22: 46177 | O22: 46177 | P22: 46178 | Q22: 46205 | R22: =IF(Q22="","",NETWORKDAYS(N22,Q22)) -> 21 | S22: 46210 | T22: =IF(S22="","",NETWORKDAYS(Q22,S22)) -> 4 | U22: 46218 | V22: =IF(U22="","",NETWORKDAYS(S22,U22)) -> 7 | W22: 46218 | X22: =IF(W22="","",NETWORKDAYS(U22,W22)) -> 1 | Y22: =IF(W22="","",NETWORKDAYS(N22,W22)) -> 30 | Z22: =IF(Y22="","",IF(Y22<=32,"EFICIENTE","NO EFICIENTE")) -> EFICIENTE | AA22: TERMINADO | AB22: MARTA MOTESINOS | AC22: 45.48 | AD22: AZUL MARIN ROJO/NEGRO BLANCO | AE22: =(((F22)/((AC22*10*4)+(AC22*12*4)))) -> 1.2493004 | AF22: 1.7 | AG22: SE DEMORA EN URDIR
A23: OP35 31 JUL | B23: ELASTICO ZAPATO REFORZADO PES 6MM | C23: JAQ#4 | D23: ELASTICO | E23: JOSE | F23: =1840+1840 -> 3680 | G23: 4269 | H23: 4002 | I23: - | J23: 352 | K23: 1.76 | L23: =+J23/G23 -> 0.082454907 | M23: 1 | N23: 46224 | O23: 46224 | P23: 46225 | Q23: 46231 | R23: =IF(Q23="","",NETWORKDAYS(N23,Q23)) -> 6 | S23: 46238 | T23: =IF(S23="","",NETWORKDAYS(Q23,S23)) -> 6 | U23: 46241 | V23: =IF(U23="","",NETWORKDAYS(S23,U23)) -> 4 | W23: 46245 | X23: =IF(W23="","",NETWORKDAYS(U23,W23)) -> 3 | Y23: =IF(W23="","",NETWORKDAYS(N23,W23)) -> 16 | Z23: =IF(Y23="","",IF(Y23<=20,"EFICIENTE","NO EFICIENTE")) -> EFICIENTE | AA23: TERMINADO | AB23: NUNE SANTIAGO | AC23: 23.76 | AD23: VARIOS | AE23: =(((F23)/((AC23*10*11)+(AC18*12*11)))) -> 0.45375631 | AF23: =29/24 -> 1.2083333
A24: OP43 JUN | B24: REATA MOCHILA DELGADA 10MM | C24: JAQ10 | D24: REATA | E24: JAVIER | F24: 6000 | G24: 5550 | H24: 5426 | I24: - | J24: 72 | K24: 0,90 | L24: =+J24/G24 -> 0.012972973 | M24: 0.85 | N24: 46190 | O24: 46189 | P24: 46192 | Q24: 46209 | R24: =IF(Q24="","",NETWORKDAYS(N24,Q24)) -> 14 | S24: 46211 | T24: =IF(S24="","",NETWORKDAYS(Q24,S24)) -> 3 | U24: 46219 | V24: =IF(U24="","",NETWORKDAYS(S24,U24)) -> 7 | W24: 46217 | X24: =IF(W24="","",NETWORKDAYS(U24,W24)) -> -3 | Y24: =IF(W24="","",NETWORKDAYS(N24,W24)) -> 20 | Z24: =IF(Y24="","",IF(Y24<=20,"EFICIENTE","NO EFICIENTE")) -> EFICIENTE | AA24: TERMINADO | AB24: CRIOLLO CRISTIAN JESUS | AC24: 84 | AD24: BLANC0 / BEIGE / PLATA FDY | AE24: =(((F24)/((AC24*10*6)+(AC24*12*6)))) -> 0.54112554 | AF24: 0.5 | AG24: SE DEMORA EN MANDAR A ENVOLTURA
A25: OP57 JUN | B25: REATA ZAPATO TUBULAR OJAL FDY 10MM | C25: JAQ5 | D25: REATA | E25: JAVIER | F25: 4000 | G25: 3664 | H25: 3300 | I25: - | J25: 203 | K25: 2.84 | L25: =+J25/G25 -> 0.05540393 | M25: 0.81 | N25: 46198 | O25: 46195 | P25: 46199 | Q25: 46211 | R25: =IF(Q25="","",NETWORKDAYS(N25,Q25)) -> 10 | S25: 46217 | T25: =IF(S25="","",NETWORKDAYS(Q25,S25)) -> 5 | U25: 46220 | V25: =IF(U25="","",NETWORKDAYS(S25,U25)) -> 4 | W25: 46225 | X25: =IF(W25="","",NETWORKDAYS(U25,W25)) -> 4 | Y25: =IF(W25="","",NETWORKDAYS(N25,W25)) -> 20 | Z25: =IF(Y25="","",IF(Y25<=20,"EFICIENTE","NO EFICIENTE")) -> EFICIENTE | AA25: TERMINADO | AB25: NUNES SANTIAGO | AC25: 41.76 | AD25: NEGRO / NEGRO/ CAFÉ/NEGRO | AE25: =(((F25)/((AC25*10*4)+(AC25*12*4)))) -> 1.0884709 | AF25: 1.13 | AG25: SE DEMORA EN URDIR Y EN ENVOLTURA
A26: OP39 JUN | B26: CORDON PLANO 160PP SUPER ANCHO PES | C26: KY#6 | D26: CORDON | E26: JAVIER | F26: 20500 | G26: 17228 | H26: 13000 | I26: - | J26: 279 | K26: 1.9 | L26: =+J26/G26 -> 0.016194567 | M26: 0.95 | N26: 46198 | O26: 46192 | P26: 46192 | Q26: 46204 | R26: =IF(Q26="","",NETWORKDAYS(N26,Q26)) -> 5 | S26: 46223 | T26: =IF(S26="","",NETWORKDAYS(Q26,S26)) -> 14 | U26: 46223 | V26: =IF(U26="","",NETWORKDAYS(S26,U26)) -> 1 | W26: 46224 | X26: =IF(W26="","",NETWORKDAYS(U26,W26)) -> 2 | Y26: =IF(W26="","",NETWORKDAYS(N26,W26)) -> 19 | Z26: =IF(Y26="","",IF(Y26<=20,"EFICIENTE","NO EFICIENTE")) -> EFICIENTE | AA26: TERMINADO | AB26: FAME | AC26: 100.32 | AD26: VERDE MILITAR | AE26: =(((F26)/((AC26*10*4)+(AC26*12*4)))) -> 2.3221147 | AF26: 2
A27: OP64 JUN | B27: REATA ZAPATO OJAL PES FDY 10MM | C27: JAQ5 | D27: REATA | E27: CLAUDIO | F27: 4000 | G27: 4657 | H27: 4400 | I27: 216 | L27: =+J27/G27 -> 0 | M27: 0.83 | N27: 46199 | O27: 46196 | P27: 46199 | Q27: 46219 | R27: =IF(Q27="","",NETWORKDAYS(N27,Q27)) -> 15 | S27: 46224 | T27: =IF(S27="","",NETWORKDAYS(Q27,S27)) -> 4 | U27: 46226 | V27: =IF(U27="","",NETWORKDAYS(S27,U27)) -> 3 | W27: 46226 | X27: =IF(W27="","",NETWORKDAYS(U27,W27)) -> 1 | Y27: =IF(W27="","",NETWORKDAYS(N27,W27)) -> 20 | Z27: =IF(Y27="","",IF(Y27<=20,"EFICIENTE","NO EFICIENTE")) -> EFICIENTE | AA27: TERMINADO | AB27: NUNEZ | AC27: 40.92 | AD27: VARIOS | AE27: =(((F27)/((AC27*10*4)+(AC27*12*4)))) -> 1.1108149 | AF27: 1.54
A28: OP04 JUL | B28: ELASTICO TEDDY FRESH 40MM | C28: JAQ#6 | D28: ELASTICO | E28: CARLOS | F28: 4000 | G28: 4390 | H28: 3750 | I28: 70 | J28: 958 | K28: 13.9 | L28: =+J28/G28 -> 0.21822323 | M28: 0.88 | N28: 46205 | O28: 46203 | P28: 46206 | Q28: 46216 | R28: =IF(Q28="","",NETWORKDAYS(N28,Q28)) -> 8 | S28: 46230 | T28: =IF(S28="","",NETWORKDAYS(Q28,S28)) -> 11 | U28: 46230 | V28: =IF(U28="","",NETWORKDAYS(S28,U28)) -> 1 | W28: 46232 | X28: =IF(W28="","",NETWORKDAYS(U28,W28)) -> 3 | Y28: =IF(W28="","",NETWORKDAYS(N28,W28)) -> 20 | Z28: =IF(Y28="","",IF(Y28<=20,"EFICIENTE","NO EFICIENTE")) -> EFICIENTE | AA28: TERMINADO | AB28: RESTREPO CRISTINA | AC28: 19.92 | AD28: NEGRO/BLANCO | AE28: =(((F28)/((AC28*10*4)+(AC28*12*4)))) -> 2.2818547 | AF28: 3.8
A29: OP13 14 JUL | B29: REATA MOCHILA DELGADA 15 10 MM | C29: JAQ#10 | D29: REATA | E29: JESSICA | F29: 6000 | G29: 7450 | H29: 6981 | I29: - | J29: 200 | K29: 2.5 | L29: =+J29/G29 -> 0.026845638 | M29: 0.84 | N29: 46206 | O29: 46204 | P29: 46206 | Q29: 46225 | R29: =IF(Q29="","",NETWORKDAYS(N29,Q29)) -> 14 | S29: 46231 | T29: =IF(S29="","",NETWORKDAYS(Q29,S29)) -> 5 | U29: 46231 | V29: =IF(U29="","",NETWORKDAYS(S29,U29)) -> 1 | W29: 46233 | X29: =IF(W29="","",NETWORKDAYS(U29,W29)) -> 3 | Y29: =IF(W29="","",NETWORKDAYS(N29,W29)) -> 20 | Z29: =IF(Y29="","",IF(Y29<=20,"EFICIENTE","NO EFICIENTE")) -> EFICIENTE | AA29: TERMINADO | AB29: CHICAIZA ROGRIGUEZ | AC29: 84 | AD29: BLANCO / PLATA/BEIGE | AE29: =(((F29)/((AC29*10*6)+(AC29*12*6)))) -> 0.54112554 | AF29: 1.04 | AG29: EN ESTA PRODUCCION SE VUEVE AUMENTAR 3 TIRAS MAS
A30: OP28 JUN | B30: REATA SANDALIA TUBULAR LUREX 25MM | C30: KY#5 | D30: REATA | E30: JOSE | F30: 6000 | G30: 6625 | H30: 6625 | I30: - | J30: 174 | K30: 4.26 | L30: =+J30/G30 -> 0.026264151 | M30: 0.8 | N30: 46177 | O30: 46177 | P30: 46178 | Q30: 46206 | R30: =IF(Q30="","",NETWORKDAYS(N30,Q30)) -> 22 | S30: 46225 | T30: =IF(S30="","",NETWORKDAYS(Q30,S30)) -> 14 | U30: 46225 | V30: =IF(U30="","",NETWORKDAYS(S30,U30)) -> 1 | W30: 46225 | X30: =IF(W30="","",NETWORKDAYS(U30,W30)) -> 1 | Y30: =IF(W30="","",NETWORKDAYS(N30,W30)) -> 35 | Z30: =IF(Y30="","",IF(Y30<=24,"EFICIENTE","NO EFICIENTE")) -> NO EFICIENTE | AA30: TERMINADO | AB30: IMPORTIZ | AC30: 45.72 | AD30: VARIOS | AE30: =(((F30)/((AC30*10*4)+(AC30*12*4)))) -> 1.4912909 | AF30: 1.875
A31: OP22 JUN | B31: REATA SANDALIA TUBULAR COCIDO INVISIBLE 20MM | C31: KY#12 | D31: REATA | E31: JAVIER | F31: 6000 | G31: 5416 | H31: 5416 | I31: - | J31: 268 | K31: 8.89 | L31: =+J31/G31 -> 0.049483013 | M31: 0.82 | N31: 46177 | O31: 46177 | P31: 46178 | Q31: 46217 | R31: =IF(Q31="","",NETWORKDAYS(N31,Q31)) -> 29 | S31: 46231 | T31: =IF(S31="","",NETWORKDAYS(Q31,S31)) -> 11 | U31: 46232 | V31: =IF(U31="","",NETWORKDAYS(S31,U31)) -> 2 | W31: 46232 | X31: =IF(W31="","",NETWORKDAYS(U31,W31)) -> 1 | Y31: =IF(W31="","",NETWORKDAYS(N31,W31)) -> 40 | Z31: =IF(Y31="","",IF(Y31<=24,"EFICIENTE","NO EFICIENTE")) -> NO EFICIENTE | AA31: TERMINADO | AB31: IMPORTIZ | AC31: 35.41 | AD31: NEGRO /CAFÉ | AE31: =(((F31)/((AC31*10*4)+(AC31*12*4)))) -> 1.9254961 | AF31: 2.31 | AG31: ESTABA PARADA HASTA QUE CLIENTE CONFIRME
A32: OP44 45 JUN | B32: REATA MOCHILA DELGADA 15 10 MM | C32: JAQ#10 | D32: REATA | E32: OSCAR | F32: 6000 | G32: 6681 | H32: 5721 | I32: - | J32: 228 | K32: 2.85 | L32: =+J32/G32 -> 0.034126628 | M32: 0.8 | N32: 46189 | O32: 46189 | P32: 46192 | Q32: 46212 | R32: =IF(Q32="","",NETWORKDAYS(N32,Q32)) -> 18 | S32: 46218 | T32: =IF(S32="","",NETWORKDAYS(Q32,S32)) -> 5 | U32: 46220 | V32: =IF(U32="","",NETWORKDAYS(S32,U32)) -> 3 | W32: 46231 | X32: =IF(W32="","",NETWORKDAYS(U32,W32)) -> 8 | Y32: =IF(W32="","",NETWORKDAYS(N32,W32)) -> 31 | Z32: =IF(Y32="","",IF(Y32<=20,"EFICIENTE","NO EFICIENTE")) -> NO EFICIENTE | AA32: TERMINADO | AB32: CRIOLLO CRISTIAN JESUS | AC32: 84 | AD32: AZUL M / PLOMO/ROSADO/BLANCO | AE32: =(((F32)/((AC32*10*6)+(AC32*12*6)))) -> 0.54112554 | AF32: 0.625 | AG32: MAQUINA CON CARGA DE TRABAJO /URDIDOS RETRASADOS
A33: OP10 JUN | B33: REATA SANDALIA TUBULAR GRUESA 2 CANALES | C33: KY15 | D33: REATA | E33: JOSE | F33: 8000 | G33: 8439 | H33: 7575 | I33: - | J33: 525 | K33: 16.28 | L33: =+J33/G33 -> 0.062211162 | M33: 0.8 | N33: 46177 | O33: 46177 | P33: 46178 | Q33: 46203 | R33: =IF(Q33="","",NETWORKDAYS(N33,Q33)) -> 19 | S33: 46218 | T33: =IF(S33="","",NETWORKDAYS(Q33,S33)) -> 12 | U33: 46220 | V33: =IF(U33="","",NETWORKDAYS(S33,U33)) -> 3 | W33: 46225 | X33: =IF(W33="","",NETWORKDAYS(U33,W33)) -> 4 | Y33: =IF(W33="","",NETWORKDAYS(N33,W33)) -> 35 | Z33: =IF(Y33="","",IF(Y33<=20,"EFICIENTE","NO EFICIENTE")) -> NO EFICIENTE | AA33: TERMINADO | AB33: MONTESINOS/IMPORTIZ/STOCK | AC33: 37.56 | AD33: AZUL MARNO/NEGRO | AE33: =(((F33)/((AC33*10*4)+(AC33*12*4)))) -> 2.4203698 | AF33: 2.75 | AG33: SE DEMORA EN URDIR Y MAQUINA CON CARGA DE TRABAJO
A34: OP29 MAY | B34: CORDON TELAR TUBULAR NYLON JAQUARD | C34: JAQ#7 | D34: CORDON | E34: JOSE | F34: 3600 | G34: 3525 | H34: 1170 | I34: 2430 | J34: 3 | K34: 0.1 | L34: =+J34/G34 -> 0.00085106383 | M34: 0.84 | N34: 46154 | O34: 46155 | P34: 46157 | Q34: 46192 | R34: =IF(Q34="","",NETWORKDAYS(N34,Q34)) -> 29 | S34: 46210 | T34: =IF(S34="","",NETWORKDAYS(Q34,S34)) -> 13 | U34: 46237 | V34: =IF(U34="","",NETWORKDAYS(S34,U34)) -> 20 | W34: 46196 | X34: =IF(W34="","",NETWORKDAYS(U34,W34)) -> -30 | Y34: =IF(W34="","",NETWORKDAYS(N34,W34)) -> 31 | Z34: =IF(Y34="","",IF(Y34<=20,"EFICIENTE","NO EFICIENTE")) -> NO EFICIENTE | AA34: TERMINADO | AB34: ARRIECHE | AC34: 16.8 | AD34: AZUL MARINO/NEGRO | AE34: =(((F34)/((AC34*10*6+(AC34*12*6))))) -> 1.6233766 | AF34: 1.04 | AG34: SE DEMORA POR MAQUINA CON CARGA DE TRABAJO
A35: OP30 JUN | B35: REATA SANDALIA TUBULAR LUREX 25MM | C35: KY#5 | D35: REATA | E35: CARLOS | F35: 6000 | G35: 7154 | H35: 6825 | I35: - | J35: 226 | K35: 543 | L35: =+J35/G35 -> 0.031590718 | M35: 0.81 | N35: 46177 | O35: 46177 | P35: 46178 | Q35: 46225 | R35: =IF(Q35="","",NETWORKDAYS(N35,Q35)) -> 35 | S35: 46230 | T35: =IF(S35="","",NETWORKDAYS(Q35,S35)) -> 4 | U35: 46231 | V35: =IF(U35="","",NETWORKDAYS(S35,U35)) -> 2 | W35: 46232 | X35: =IF(W35="","",NETWORKDAYS(U35,W35)) -> 2 | Y35: =IF(W35="","",NETWORKDAYS(N35,W35)) -> 40 | Z35: =IF(Y35="","",IF(Y35<=24,"EFICIENTE","NO EFICIENTE")) -> NO EFICIENTE | AA35: TERMINADO | AB35: IMPORTIZ | AC35: 45.72 | AD35: NEGRO/AZUL M/NEGRO/CAFÉ | AE35: =(((F35)/((AC35*10*4)+(AC35*12*4)))) -> 1.4912909 | AF35: 2 | AG35: URDIDO A LA FILA
A36: OP13 JUN | B36: REATA SANDALIA EMPALMADA MULTICOLOR | C36: KY#14 | D36: REATA | E36: CARLOS | F36: 18000 | G36: 3447 | H36: 3250 | I36: - | J36: 578 | K36: 12.25 | L36: =+J36/G36 -> 0.16768204 | M36: 0.74 | N36: 46177 | O36: 46178 | P36: 46178 | Q36: 46190 | R36: =IF(Q36="","",NETWORKDAYS(N36,Q36)) -> 10 | S36: 46232 | T36: =IF(S36="","",NETWORKDAYS(Q36,S36)) -> 31 | U36: 46237 | V36: =IF(U36="","",NETWORKDAYS(S36,U36)) -> 4 | W36: 46238 | X36: =IF(W36="","",NETWORKDAYS(U36,W36)) -> 2 | Y36: =IF(W36="","",NETWORKDAYS(N36,W36)) -> 44 | Z36: =IF(Y36="","",IF(Y36<=20,"EFICIENTE","NO EFICIENTE")) -> NO EFICIENTE | AA36: TERMINADO | AB36: IMPORTIZ | AC36: 34.08 | AD36: NEGRO/CAFÉ | AE36: =(((F36)/((AC36*10*4)+(AC40*12*4)))) -> 3.1833616 | AF36: 1.41 | AG36: SE TIENE QUE CAMBIAR EL RENDIMIENTO / SE DEMORA POR MAQUINA CON CARGA DE TRABAJO
A37: OP51 JUN | B37: ELASTICO CONFECCION FAJAS MEDICAS NYLON 25MM | C37: JAQ13 | D37: ELASTICO | E37: OSCAR | F37: 6000 | G37: 5229 | H37: 5724 | I37: - | J37: 104 | K37: 2.1 | L37: =+J37/G37 -> 0.01988908 | M37: 0.88 | N37: 46197 | O37: 46197 | P37: 46199 | Q37: 46225 | R37: =IF(Q37="","",NETWORKDAYS(N37,Q37)) -> 21 | S37: 46233 | T37: =IF(S37="","",NETWORKDAYS(Q37,S37)) -> 7 | U37: 46237 | V37: =IF(U37="","",NETWORKDAYS(S37,U37)) -> 3 | W37: 46240 | X37: =IF(W37="","",NETWORKDAYS(U37,W37)) -> 4 | Y37: =IF(W37="","",NETWORKDAYS(N37,W37)) -> 32 | Z37: =IF(Y37="","",IF(Y37<=20,"EFICIENTE","NO EFICIENTE")) -> NO EFICIENTE | AA37: TERMINADO | AB37: NUNEZ / BUENANO | AC37: 19.44 | AD37: BLANCO/CRUDO | AE37: =(((F37)/((AC37*10*6)+(AC37*12*6)))) -> 2.3381968 | AF37: 3.79 | AG37: MAQUINA CON CARGA DE TRABAJO RETRASADOS
A38: OP35 JUN | B38: CORDON RACHELL | C38: RACHELL | D38: CORDON | E38: CARLOS | F38: 4200 | G38: 3656 | H38: 1235 | I38: 609 | J38: 97 | K38: 0.62 | L38: =+J38/G38 -> 0.026531729 | M38: 0.8 | N38: 46190 | O38: 46190 | P38: 46192 | Q38: 46199 | R38: =IF(Q38="","",NETWORKDAYS(N38,Q38)) -> 8 | S38: 46206 | T38: =IF(S38="","",NETWORKDAYS(Q38,S38)) -> 6 | U38: 46224 | V38: =IF(U38="","",NETWORKDAYS(S38,U38)) -> 13 | W38: 46224 | X38: =IF(W38="","",NETWORKDAYS(U38,W38)) -> 1 | Y38: =IF(W38="","",NETWORKDAYS(N38,W38)) -> 25 | Z38: =IF(Y38="","",IF(Y38<=20,"EFICIENTE","NO EFICIENTE")) -> NO EFICIENTE | AA38: TERMINADO | AB38: OCHOA | AC38: 18.72 | AD38: TURQUEZA | AE38: =(((F38)/((AC38*10*9+(AC38*12*9))))) -> 1.1331261 | AF38: 2.1
A39: OP15 16 JUL | B39: ELASTICO CROCHET 20 15 MM | C39: KY#10 | D39: ELASTICO | E39: JOSE | F39: =10350+10350 -> 20700 | G39: 6628 | H39: 6247 | I39: - | L39: =+J39/G39 -> 0 | M39: 0.85 | N39: 46177 | O39: 46179 | P39: 46212 | Q39: 46223 | R39: =IF(Q39="","",NETWORKDAYS(N39,Q39)) -> 33 | S39: 46232 | T39: =IF(S39="","",NETWORKDAYS(Q39,S39)) -> 8 | U39: 46234 | V39: =IF(U39="","",NETWORKDAYS(S39,U39)) -> 3 | W39: 46245 | X39: =IF(W39="","",NETWORKDAYS(U39,W39)) -> 8 | Y39: =IF(W39="","",NETWORKDAYS(N39,W39)) -> 49 | Z39: =IF(Y39="","",IF(Y39<=20,"EFICIENTE","NO EFICIENTE")) -> NO EFICIENTE | AA39: TERMINADO | AB39: NUNEZ RAUL | AC39: 25.56 | AD39: BLANCO | AE39: =(((F39)/((AC39*10*11)+(AC44*12*11)))) -> 4.5454545 | AF39: =22.5/24 -> 0.9375
A40: OP20 JUL | B40: REATA ZAPATO TAFETA DELGADA 20MM | C40: KY#17 | D40: REATA | E40: OSCAR | F40: 10000 | G40: 10054 | H40: 9950 | I40: - | J40: 561 | K40: 3.59 | L40: =+J40/G40 -> 0.055798687 | M40: 0.84 | N40: 46216 | O40: 46216 | P40: 46224 | Q40: 46232 | R40: =IF(Q40="","",NETWORKDAYS(N40,Q40)) -> 13 | S40: 46239 | T40: =IF(S40="","",NETWORKDAYS(Q40,S40)) -> 6 | U40: 46241 | V40: =IF(U40="","",NETWORKDAYS(S40,U40)) -> 3 | W40: 46245 | X40: =IF(W40="","",NETWORKDAYS(U40,W40)) -> 3 | Y40: =IF(W40="","",NETWORKDAYS(N40,W40)) -> 22 | Z40: =IF(Y40="","",IF(Y40<=20,"EFICIENTE","NO EFICIENTE")) -> NO EFICIENTE | AA40: TERMINADO | AB40: NUNEZ SANTIAGO | AC40: 89.4 | AD40: NEGRO | AE40: =(((F40)/((AC40*10*4)+(AC19*12*4)))) -> 1.3144059 | AF40: =25/24 -> 1.0416667
...

Sheet MONTAJE 
A1: ORDENES DE PRODUCCION JULIO | B1: AMPARO | C1: JESSICA | D1: EVELYN | E1: ALEXANDER
A2: OP36 JUN | B2: 3.5 | C2: 3.5
A3: OP38 JUN | C3: 6
A4: OP15 JUN | B4: 2 | C4: 2
A5: OP05 JUL | D5: 6
A6: OP49 JUN | C6: 6
A7: OP46 47 JUN | B7: 2 | D7: 2
A8: OP59 JUN | B8: 3 | C8: 3
A9: OP58 JUN | B9: 3 | C9: 3
A10: OP48 JUN | B10: 2 | D10: 2
A11: OP11 12 JUL | C11: 2 | E11: 6
A12: OP02 JUL | B12: 6
A13: OP19 26 JUL | B13: 4.5 | D13: 4.5
A14: OP29 JUL | B14: 3 | E14: 3
A15: OP50 JUN | D15: 6
A16: OP25 30 JUL | C16: 24
A17: OP22 JUL | B17: 1.5 | C17: 1.5 | E17: 1
A18: OP33 34 JUL | B18: 3 | D18: 3
A19: OP34 JUN | B19: 1 | C19: 6
A20: OP07 JUL | B20: 6.5 | C20: 1 | D20: 0.5
A21: OP26 27 JUN | B21: 0.5 | C21: 3.5
A22: OP35 31 JUL | B22: 3 | E22: 3
A23: OP43 JUN | C23: 6
A24: OP57 JUN | B24: 2 | C24: 2
A25: OP39 JUN | D25: 7
A26: OP64 JUN | C26: 4
A27: OP04 JUL | B27: 2 | C27: 1 | D27: 1
A28: OP13 14 JUL | B28: 4 | D28: 2 | E28: 3
A29: OP28 JUN | B29: 2 | D29: 2
A30: OP22 JUN | B30: 1.5 | C30: 1.5 | E30: 1
A31: OP44 45 JUN | B31: 3 | D31: 3
A32: OP10 JUN | B32: 2 | C32: 2
A33: OP29 MAY | B33: 6
A34: OP30 JUN | B34: 2 | E34: 2
A35: OP13 JUN | B35: 2 | E35: 2
A36: OP51 JUN | B36: 3 | D36: 0.5 | E36: 2.5
A37: OP35 JUN | B37: 4.5 | C37: 4.5
A38: OP15 16 JUL | B38: 3.6 | C38: 3.6 | E38: 3.6
A39: OP20 JUL | D39: 6
A40: OP33 JUN | B40: 2 | E40: 2
...

Sheet CALIBRACIONES
A1: CALIBRACION MES DE JULIO
A2: N | B2: NOMBRE | C2: NUMERO DE VECES | D2: ARTICULO | E2: OBSERVACIONES
A3: 1 | B3: CARLOS | C3: =COUNTIF('DATOS GENERALES'!A:AG,CALIBRACIONES!B3) -> 8 | D3: 6 REATAS, 3 CORDON, 1 ELASTICO
A4: 2 | B4: OSCAR | C4: =COUNTIF('DATOS GENERALES'!E:E,CALIBRACIONES!B4) -> 13 | D4: 6 REATAS, 2 ELASTICOS
A5: 3 | B5: JOSE | C5: =COUNTIF('DATOS GENERALES'!E:E,CALIBRACIONES!B5) -> 10 | D5: 2 CORDON, 2 REATAS, 2 ELASTICOS
A6: 4 | B6: CLAUDIO | C6: =COUNTIF('DATOS GENERALES'!E:E,CALIBRACIONES!B6) -> 7 | D6: 4 RETAS, 2 ELASTICOS
A7: 5 | B7: JAVIER | C7: =COUNTIF('DATOS GENERALES'!E:E,CALIBRACIONES!B7) -> 12 | D7: 7 REATAS, 5 ELASTICOS , 1 CORDON
A8: 6 | B8: JESSICA | C8: =COUNTIF('DATOS GENERALES'!E:E,CALIBRACIONES!B8) -> 4 | D8: 1 REATA, 1 CORDON
A10: TOTAL | C10: =SUM(C3:C8) -> 54 | D10: 45
C11: =D10*100%/55 -> 0.81818182 | D11: =5/6 -> 0.83333333 | E11: =C10/6 -> 9
